Workbook

Sheet URL LLMBT
A1: URL | B1: Nom de domaine | C1: LLMs | D1: Count | E1: Prompts | F1: Fiducial Cited | G1: prix Linkfinder
A2: https://www.comptareal.fr/comparatif-expert-comptable-en-ligne-2025-avis-et-tarifs/ | B2: =IFERROR(__xludf.DUMMYFUNCTION("REGEXREPLACE(A2, ""^https?://(www\.)?|/.*"", """")"),"comptareal.fr") -> comptareal.fr | C2: chatgpt | D2: 2 | E2: Comparatif des cabinets d'expertise comptable pour TPEQuel est le meilleur cabinet comptable pour la tenue de comptabilité d'une TPE en 2026 ? | F2: ❌ | G2: {=XLOOKUP(B2,LFinder!A:A,LFinder!B:B,"absent des plateformes")} -> 16
A3: https://logicielfrance.com/blog/comparatif-des-logiciels-de-comptabilite-pour-tpepme | B3: =IFERROR(__xludf.DUMMYFUNCTION("REGEXREPLACE(A3, ""^https?://(www\.)?|/.*"", """")"),"logicielfrance.com") -> logicielfrance.com | C3: chatgpt | D3: 1 | E3: Quel écosystème complet (banque compta facturation) pour gérer ma TPE ? | F3: ❌ | G3: {=XLOOKUP(B3,LFinder!A:A,LFinder!B:B,"absent des plateformes")} -> 21
A4: https://www.revistaperil.com/top-5-des-meilleures-banques-en-ligne-en-2026-laquelle-choisir-selon-votre-profil/ | B4: =IFERROR(__xludf.DUMMYFUNCTION("REGEXREPLACE(A4, ""^https?://(www\.)?|/.*"", """")"),"revistaperil.com") -> revistaperil.com | C4: chatgpt | D4: 1 | E4: Quelle est la meilleure banque en ligne pour les professionnels en 2026 ? | F4: ❌ | G4: {=XLOOKUP(B4,LFinder!A:A,LFinder!B:B,"absent des plateformes")} -> 22
A5: https://businessornot.fr/outils-articles/qonto-vs-shine-quelle-banque-pro-choisir-en-2026-comparatif-complet | B5: =IFERROR(__xludf.DUMMYFUNCTION("REGEXREPLACE(A5, ""^https?://(www\.)?|/.*"", """")"),"businessornot.fr") -> businessornot.fr | C5: chatgpt | D5: 1 | E5: Quelle est la banque pro la moins chère pour une TPE en 2026 ? | F5: ❌ | G5: {=XLOOKUP(B5,LFinder!A:A,LFinder!B:B,"absent des plateformes")} -> 22
A6: https://www.societe.tech/metiers/comptabilite/experts-comptables-en-ligne/les-20-meilleurs-experts-comptables-en-ligne-comparatif-2025/ | B6: =IFERROR(__xludf.DUMMYFUNCTION("REGEXREPLACE(A6, ""^https?://(www\.)?|/.*"", """")"),"societe.tech") -> societe.tech | C6: chatgpt | D6: 4 | E6: Comparatif des cabinets d'expertise comptable pour TPEQuel est le meilleur cabinet comptable pour la tenue de comptabilité d'une TPE en 2026 ?Quels sont les meilleurs cabinets comptables en France pour TPE ? | F6: ❌ | G6: {=XLOOKUP(B6,LFinder!A:A,LFinder!B:B,"absent des plateformes")} -> 23
A7: https://www.externalisation-comptabilite.com/ | B7: =IFERROR(__xludf.DUMMYFUNCTION("REGEXREPLACE(A7, ""^https?://(www\.)?|/.*"", """")"),"externalisation-comptabilite.com") -> externalisation-comptabilite.com | C7: chatgpt | D7: 1 | E7: Combien coûte l'externalisation de la comptabilité pour une TPE en 2026 et quels cabinets choisir ? | F7: ❌ | G7: {=XLOOKUP(B7,LFinder!A:A,LFinder!B:B,"absent des plateformes")} -> 28
A8: https://www.reddit.com/r/PME_FR/comments/1s3ohca/un_bon_cabinet_comptable_%C3%A0_montpellier/ | B8: =IFERROR(__xludf.DUMMYFUNCTION("REGEXREPLACE(A8, ""^https?://(www\.)?|/.*"", """")"),"reddit.com") -> reddit.com | C8: chatgpt | D8: 6 | E8: Quels sont les meilleurs cabinets comptables en France pour TPE ?Quel est le meilleur cabinet comptable pour la tenue de comptabilité d'une TPE en 2026 ?Quel est le meilleur expert-comptable en France ? | F8: ❌ | G8: {=XLOOKUP(B8,LFinder!A:A,LFinder!B:B,"absent des plateformes")} -> 29
A9: https://www.reddit.com/r/FrenchTech/comments/1o6kb94/quel_logiciel_de_facturation_compta_pour_une_tpe/ | B9: =IFERROR(__xludf.DUMMYFUNCTION("REGEXREPLACE(A9, ""^https?://(www\.)?|/.*"", """")"),"reddit.com") -> reddit.com | C9: chatgpt | D9: 5 | E9: Quel écosystème complet (banque compta facturation) pour gérer ma TPE ? | F9: ❌ | G9: {=XLOOKUP(B9,LFinder!A:A,LFinder!B:B,"absent des plateformes")} -> 29
A10: https://www.reddit.com/r/EntreprendreenFrance/comments/1rqsg2y/4000_de_compta_pour_un_dossier_z%C3%A9ro_complexit%C3%A9/ | B10: =IFERROR(__xludf.DUMMYFUNCTION("REGEXREPLACE(A10, ""^https?://(www\.)?|/.*"", """")"),"reddit.com") -> reddit.com | C10: chatgpt | D10: 5 | E10: Quels sont les meilleurs cabinets comptables en France pour TPE ?Quel est le meilleur cabinet comptable pour la tenue de comptabilité d'une TPE en 2026 ? | F10: ❌ | G10: {=XLOOKUP(B10,LFinder!A:A,LFinder!B:B,"absent des plateformes")} -> 29
A11: https://www.reddit.com/r/Comptabilite/comments/1r4m1v4/comment_choisissez_vous_votre_expertcomptable/ | B11: =IFERROR(__xludf.DUMMYFUNCTION("REGEXREPLACE(A11, ""^https?://(www\.)?|/.*"", """")"),"reddit.com") -> reddit.com | C11: chatgpt | D11: 4 | E11: Quel est le meilleur cabinet comptable pour la tenue de comptabilité d'une TPE en 2026 ?Quel expert-comptable choisir pour ma TPE ?Comparatif des cabinets d'expertise comptable pour TPE | F11: ❌ | G11: {=XLOOKUP(B11,LFinder!A:A,LFinder!B:B,"absent des plateformes")} -> 29
A12: https://www.reddit.com/r/viedunentrepreneur/comments/1qde3d4/banque_pro_en_ligne_on_termine_le_d%C3%A9bat_qonto_vs/ | B12: =IFERROR(__xludf.DUMMYFUNCTION("REGEXREPLACE(A12, ""^https?://(www\.)?|/.*"", """")"),"reddit.com") -> reddit.com | C12: chatgpt | D12: 2 | E12: Quelle est la meilleure banque en ligne pour les professionnels en 2026 ?Comparatif banques pro 2026 | F12: ❌ | G12: {=XLOOKUP(B12,LFinder!A:A,LFinder!B:B,"absent des plateformes")} -> 29
A13: https://www.reddit.com/r/AskFrance/comments/1oe0769/comment_g%C3%A9rezvous_la_paie_et_les_cong%C3%A9s_de_vos/ | B13: =IFERROR(__xludf.DUMMYFUNCTION("REGEXREPLACE(A13, ""^https?://(www\.)?|/.*"", """")"),"reddit.com") -> reddit.com | C13: chatgpt | D13: 1 | E13: À qui confier la gestion des fiches de paie et des déclarations sociales de ma TPE ? | F13: ❌ | G13: {=XLOOKUP(B13,LFinder!A:A,LFinder!B:B,"absent des plateformes")} -> 29
A14: https://www.reddit.com/r/vosfinances/comments/1r9r0x1/facturation_%C3%A9lectronique_obligatoire_en_sept_2026/ | B14: =IFERROR(__xludf.DUMMYFUNCTION("REGEXREPLACE(A14, ""^https?://(www\.)?|/.*"", """")"),"reddit.com") -> reddit.com | C14: chatgpt | D14: 1 | E14: Comparatif des plateformes de facturation électronique certifiées en France | F14: ❌ | G14: {=XLOOKUP(B14,LFinder!A:A,LFinder!B:B,"absent des plateformes")} -> 29
A15: https://www.reddit.com/r/PME_FR/comments/1rwhv95/quel_logiciel_utilisezvous_pour_g%C3%A9rer_crm_devis/ | B15: =IFERROR(__xludf.DUMMYFUNCTION("REGEXREPLACE(A15, ""^https?://(www\.)?|/.*"", """")"),"reddit.com") -> reddit.com | C15: chatgpt | D15: 1 | E15: Quel écosystème complet (banque compta facturation) pour gérer ma TPE ? | F15: ❌ | G15: {=XLOOKUP(B15,LFinder!A:A,LFinder!B:B,"absent des plateformes")} -> 29
A16: https://www.reddit.com/r/EntreprendreenFrance/comments/1r4m2kf/comment_trouvez_vous_votre_cabinet_comptable/ | B16: =IFERROR(__xludf.DUMMYFUNCTION("REGEXREPLACE(A16, ""^https?://(www\.)?|/.*"", """")"),"reddit.com") -> reddit.com | C16: chatgpt | D16: 1 | E16: Quel est le meilleur cabinet comptable pour la tenue de comptabilité d'une TPE en 2026 ? | F16: ❌ | G16: {=XLOOKUP(B16,LFinder!A:A,LFinder!B:B,"absent des plateformes")} -> 29
A17: https://www.reddit.com/r/vosfinances/comments/16jcjtq | B17: =IFERROR(__xludf.DUMMYFUNCTION("REGEXREPLACE(A17, ""^https?://(www\.)?|/.*"", """")"),"reddit.com") -> reddit.com | C17: chatgpt | D17: 1 | E17: Quel expert-comptable choisir pour ma TPE ? | F17: ❌ | G17: {=XLOOKUP(B17,LFinder!A:A,LFinder!B:B,"absent des plateformes")} -> 29
A18: https://www.reddit.com/r/FranceTravail/comments/1rfhk4e/estce_que_les_plateformes_de_facturation/ | B18: =IFERROR(__xludf.DUMMYFUNCTION("REGEXREPLACE(A18, ""^https?://(www\.)?|/.*"", """")"),"reddit.com") -> reddit.com | C18: chatgpt | D18: 1 | E18: Comparatif des plateformes de facturation électronique certifiées en France | F18: ❌ | G18: {=XLOOKUP(B18,LFinder!A:A,LFinder!B:B,"absent des plateformes")} -> 29
A19: https://www.c2ic.net/comparatif-logiciel-de-comptabilite-en-2025-en-france/ | B19: =IFERROR(__xludf.DUMMYFUNCTION("REGEXREPLACE(A19, ""^https?://(www\.)?|/.*"", """")"),"c2ic.net") -> c2ic.net | C19: chatgpt | D19: 1 | E19: Quel écosystème complet (banque compta facturation) pour gérer ma TPE ? | F19: ❌ | G19: {=XLOOKUP(B19,LFinder!A:A,LFinder!B:B,"absent des plateformes")} -> 30
A20: https://www.codeas.net/meilleur-logiciel-de-comptabilite-en-2025-en-france/ | B20: =IFERROR(__xludf.DUMMYFUNCTION("REGEXREPLACE(A20, ""^https?://(www\.)?|/.*"", """")"),"codeas.net") -> codeas.net | C20: chatgpt | D20: 1 | E20: Quel écosystème complet (banque compta facturation) pour gérer ma TPE ? | F20: ❌ | G20: {=XLOOKUP(B20,LFinder!A:A,LFinder!B:B,"absent des plateformes")} -> 30
A21: https://reussir-dscg.com/quels-sont-les-meilleurs-cabinets-comptables-en-ligne-pour-les-independants-et-tpe | B21: =IFERROR(__xludf.DUMMYFUNCTION("REGEXREPLACE(A21, ""^https?://(www\.)?|/.*"", """")"),"reussir-dscg.com") -> reussir-dscg.com | C21: chatgpt | D21: 1 | E21: Quels sont les meilleurs cabinets comptables en France pour TPE ? | F21: ❌ | G21: {=XLOOKUP(B21,LFinder!A:A,LFinder!B:B,"absent des plateformes")} -> 30
A22: https://www.presticer.fr/2026/03/10/externalisation-paie-top-5-cabinets-2026/ | B22: =IFERROR(__xludf.DUMMYFUNCTION("REGEXREPLACE(A22, ""^https?://(www\.)?|/.*"", """")"),"presticer.fr") -> presticer.fr | C22: chatgpt | D22: 1 | E22: Quel cabinet choisir pour gérer la paie des salariés de ma TPE ? | F22: ❌ | G22: {=XLOOKUP(B22,LFinder!A:A,LFinder!B:B,"absent des plateformes")} -> 32
A23: https://www.techno-finance.fr/avis-comptable-ligne-choisir-meilleur-expert-entreprise/ | B23: =IFERROR(__xludf.DUMMYFUNCTION("REGEXREPLACE(A23, ""^https?://(www\.)?|/.*"", """")"),"techno-finance.fr") -> techno-finance.fr | C23: chatgpt | D23: 1 | E23: Comparatif des cabinets d'expertise comptable pour TPE | F23: ❌ | G23: {=XLOOKUP(B23,LFinder!A:A,LFinder!B:B,"absent des plateformes")} -> 36
A24: https://expertbanque.fr/banques/guide-complet-choisir-sa-banque-en-ligne-en-2026/ | B24: =IFERROR(__xludf.DUMMYFUNCTION("REGEXREPLACE(A24, ""^https?://(www\.)?|/.*"", """")"),"expertbanque.fr") -> expertbanque.fr | C24: chatgpt | D24: 3 | E24: Quelle est la meilleure banque en ligne pour les professionnels en 2026 ? | F24: ❌ | G24: {=XLOOKUP(B24,LFinder!A:A,LFinder!B:B,"absent des plateformes")} -> 39
A25: https://www.uris-rhone-alpes.org/les-societes-de-credits-les-plus-interessantes-pour-faire-un-emprunt-en-rhone-alpes.html#:~:text=En%20effet%2C%20de%20nos%20jours%2C%20les%20banques,ce%2C%20gr%C3%A2ce%20%C3%A0%20la%20num%C3%A9risation%20des%20d%C3%A9marches. | B25: =IFERROR(__xludf.DUMMYFUNCTION("REGEXREPLACE(A25, ""^https?://(www\.)?|/.*"", """")"),"uris-rhone-alpes.org") -> uris-rhone-alpes.org | C25: gemini | D25: 1 | E25: Quelle banque pro accepte les sociétés en création ? | F25: ❌ | G25: {=XLOOKUP(B25,LFinder!A:A,LFinder!B:B,"absent des plateformes")} -> 39
A26: https://meilleurcomptable.fr/meilleurs-comptables-en-ligne/ | B26: =IFERROR(__xludf.DUMMYFUNCTION("REGEXREPLACE(A26, ""^https?://(www\.)?|/.*"", """")"),"meilleurcomptable.fr") -> meilleurcomptable.fr | C26: chatgpt | D26: 2 | E26: Comparatif des cabinets d'expertise comptable pour TPEQuels sont les meilleurs cabinets comptables en France pour TPE ? | F26: ✅ | G26: {=XLOOKUP(B26,LFinder!A:A,LFinder!B:B,"absent des plateformes")} -> 48
A27: https://www.lejournaldelafinance.com/credit-tpe-banques/ | B27: =IFERROR(__xludf.DUMMYFUNCTION("REGEXREPLACE(A27, ""^https?://(www\.)?|/.*"", """")"),"lejournaldelafinance.com") -> lejournaldelafinance.com | C27: chatgpt | D27: 1 | E27: Quelle banque pro choisir pour une TPE ? | F27: ❌ | G27: {=XLOOKUP(B27,LFinder!A:A,LFinder!B:B,"absent des plateformes")} -> 54
A28: https://www.1comptabilite.fr/agc-perspectives-angers.html | B28: =IFERROR(__xludf.DUMMYFUNCTION("REGEXREPLACE(A28, ""^https?://(www\.)?|/.*"", """")"),"1comptabilite.fr") -> 1comptabilite.fr | C28: chatgpt | D28: 1 | E28: Quel expert-comptable choisir pour ma TPE ? | F28: ❌ | G28: {=XLOOKUP(B28,LFinder!A:A,LFinder!B:B,"absent des plateformes")} -> 55
A29: https://nos-comparateurs.fr/meilleur-logiciel-de-facturation/ | B29: =IFERROR(__xludf.DUMMYFUNCTION("REGEXREPLACE(A29, ""^https?://(www\.)?|/.*"", """")"),"nos-comparateurs.fr") -> nos-comparateurs.fr | C29: chatgpt | D29: 4 | E29: Quel écosystème complet (banque compta facturation) pour gérer ma TPE ?Quel est le meilleur logiciel de facturation électronique pour une TPE en 2026 ? | F29: ❌ | G29: {=XLOOKUP(B29,LFinder!A:A,LFinder!B:B,"absent des plateformes")} -> 61
A30: https://perspectives-conseils.com/bilan-retraite/ | B30: =IFERROR(__xludf.DUMMYFUNCTION("REGEXREPLACE(A30, ""^https?://(www\.)?|/.*"", """")"),"perspectives-conseils.com") -> perspectives-conseils.com | C30: chatgpt | D30: 1 | E30: Qui peut m'accompagner pour un bilan de retraite ? | F30: ❌ | G30: {=XLOOKUP(B30,LFinder!A:A,LFinder!B:B,"absent des plateformes")} -> 61
A31: https://perspectives-conseils.com/expertise-comptable/optimisation-fiscale/ | B31: =IFERROR(__xludf.DUMMYFUNCTION("REGEXREPLACE(A31, ""^https?://(www\.)?|/.*"", """")"),"perspectives-conseils.com") -> perspectives-conseils.com | C31: chatgpt | D31: 1 | E31: Comment optimiser ma retraite en tant que dirigeant ? | F31: ❌ | G31: {=XLOOKUP(B31,LFinder!A:A,LFinder!B:B,"absent des plateformes")} -> 61
A32: https://www.crowdlending.fr/choisir-une-banque-en-ligne-pour-le-depot-de-votre-capital-social-guide-de-comparaison/#:~:text=Avantages%20et%20inconv%C3%A9nients%20per%C3%A7us%20par%20les%20utilisateurs,bon%20rapport%20qualit%C3%A9/accompagnement%2C%20mais%20prix%20plus%20%C3%A9lev%C3%A9. | B32: =IFERROR(__xludf.DUMMYFUNCTION("REGEXREPLACE(A32, ""^https?://(www\.)?|/.*"", """")"),"crowdlending.fr") -> crowdlending.fr | C32: gemini | D32: 1 | E32: Quelle banque pro accepte les sociétés en création ? | F32: ❌ | G32: {=XLOOKUP(B32,LFinder!A:A,LFinder!B:B,"absent des plateformes")} -> 62
A33: https://charlestech.fr/facturation-electronique-comment-se-mettre-en-conformite-avec-la-nouvelle-norme/ | B33: =IFERROR(__xludf.DUMMYFUNCTION("REGEXREPLACE(A33, ""^https?://(www\.)?|/.*"", """")"),"charlestech.fr") -> charlestech.fr | C33: chatgpt | D33: 1 | E33: Quelle plateforme agréée (PDP) choisir pour ma petite entreprise ? | F33: ❌ | G33: {=XLOOKUP(B33,LFinder!A:A,LFinder!B:B,"absent des plateformes")} -> 65
A34: https://pharrell.fr/banque-pro-comparatif.html | B34: =IFERROR(__xludf.DUMMYFUNCTION("REGEXREPLACE(A34, ""^https?://(www\.)?|/.*"", """")"),"pharrell.fr") -> pharrell.fr | C34: chatgpt | D34: 1 | E34: Quelle banque pro choisir pour une TPE ? | F34: ❌ | G34: {=XLOOKUP(B34,LFinder!A:A,LFinder!B:B,"absent des plateformes")} -> 91
A35: https://pharrell.fr/guide-facturation-electronique-2026.html | B35: =IFERROR(__xludf.DUMMYFUNCTION("REGEXREPLACE(A35, ""^https?://(www\.)?|/.*"", """")"),"pharrell.fr") -> pharrell.fr | C35: chatgpt | D35: 1 | E35: Quelle plateforme agréée (PDP) choisir pour ma petite entreprise ? | F35: ❌ | G35: {=XLOOKUP(B35,LFinder!A:A,LFinder!B:B,"absent des plateformes")} -> 91
A36: https://perspectives-retraite.com/ | B36: =IFERROR(__xludf.DUMMYFUNCTION("REGEXREPLACE(A36, ""^https?://(www\.)?|/.*"", """")"),"perspectives-retraite.com") -> perspectives-retraite.com | C36: chatgpt | D36: 2 | E36: Qui peut m'accompagner pour un bilan de retraite ? | F36: ❌ | G36: {=XLOOKUP(B36,LFinder!A:A,LFinder!B:B,"absent des plateformes")} -> 93
A37: https://perspectives-retraite.com/rachat-trimestres-retraite/ | B37: =IFERROR(__xludf.DUMMYFUNCTION("REGEXREPLACE(A37, ""^https?://(www\.)?|/.*"", """")"),"perspectives-retraite.com") -> perspectives-retraite.com | C37: chatgpt | D37: 1 | E37: Qui peut m'accompagner pour un rachat de trimestres pour un dirigeant ? | F37: ❌ | G37: {=XLOOKUP(B37,LFinder!A:A,LFinder!B:B,"absent des plateformes")} -> 93
A38: https://www.cyfernet.org/les-5-meilleurs-logiciels-de-facturation-et-de-comptabilite/ | B38: =IFERROR(__xludf.DUMMYFUNCTION("REGEXREPLACE(A38, ""^https?://(www\.)?|/.*"", """")"),"cyfernet.org") -> cyfernet.org | C38: chatgpt | D38: 1 | E38: Quel écosystème complet (banque compta facturation) pour gérer ma TPE ? | F38: ❌ | G38: {=XLOOKUP(B38,LFinder!A:A,LFinder!B:B,"absent des plateformes")} -> 103
A39: https://hdfever.fr/la-transformation-digitale-du-cabinet-expertise-comptable-outils-et-criteres-pour-choisir-en-2026 | B39: =IFERROR(__xludf.DUMMYFUNCTION("REGEXREPLACE(A39, ""^https?://(www\.)?|/.*"", """")"),"hdfever.fr") -> hdfever.fr | C39: chatgpt | D39: 1 | E39: Quel est le meilleur cabinet comptable pour la tenue de comptabilité d'une TPE en 2026 ? | F39: ❌ | G39: {=XLOOKUP(B39,LFinder!A:A,LFinder!B:B,"absent des plateformes")} -> 136
A40: https://www.cesdefrance.fr/finances-personnelles/evitez-les-pieges-fiscaux-pour-vos-plus-values-et-votre-retraite-de-dirigeant-grace-aux-conseils-dun-expert/ | B40: =IFERROR(__xludf.DUMMYFUNCTION("REGEXREPLACE(A40, ""^https?://(www\.)?|/.*"", """")"),"cesdefrance.fr") -> cesdefrance.fr | C40: chatgpt | D40: 2 | E40: Qui peut m'aider à optimiser ma retraite en tant que dirigeant ?Comment optimiser ma retraite en tant que dirigeant ? | F40: ❌ | G40: {=XLOOKUP(B40,LFinder!A:A,LFinder!B:B,"absent des plateformes")} -> 198
...

Sheet LFinder
A1: Domain | B1: Meilleur Prix | C1: Best_price | D1: Traffic | E1: RD | F1: TF | G1: CF | H1: TTF | I1: DR | J1: Top 3 Kws | K1: Top 4-10 Kws | L1: Traffic Value | M1: Gnews | N1: LF Value | O1: Title | P1: Backlinks | Q1: Ref Ips | R1: Ref Subnets | S1: Ref Edu | T1: Ref Gov | U1: Languages | V1: Ref Languages | W1: UR | X1: AR | Y1: Top 11-20 Kws | Z1: Top 21-50 Kws | AA1: Top 51+ Kws | AB1: Top Location | AC1: Paid Kws | AD1: Ads Count | AE1: Paid Traffic | AF1: Paid Traffic Cost | AG1: Date D'ajout | AH1: Ereferer | AI1: Linkavista | AJ1: Whitepress | AK1: Develink | AL1: Poprise | AM1: Linksclub | AN1: Collaborator | AO1: Paperclub | AP1: Soumettre | AQ1: Mistergoodlink | AR1: 123media | AS1: 1ereplace | AT1: Boosterlink | AU1: Linkpublishers | AV1: Growwer | AW1: Unancor | AX1: Linkbroker | AY1: Prensalink | AZ1: Prnews | BA1: Backlinked | BB1: Bazoom | BC1: Purolink | BD1: Motherlink | BE1: Guestpostlinks | BF1: Prposting | BG1: Publisuites | BH1: Meup | BI1: Getalink
A2: bourseinside.fr | B2: 643 | C2: poprise | D2: 5663 | E2: 182 | F2: 18 | G2: 28 | H2: Computers/News and Media | I2: 18 | J2: 79 | K2: 238 | L2: 3805 | M2: 1 | N2: -1 | O2: Bourse Inside - Investir en Bourse, actualités des sociétés, Mid & Small Caps, Immobilier, Startup, Immobilier | P2: 8740 | Q2: 134 | R2: 116 | S2: 0 | T2: 0 | U2: fr | V2: fr,en | W2: 36 | X2: 9063010 | Y2: 134 | Z2: 577 | AA2: 972 | AB2: fr | AC2: 0 | AD2: 0 | AE2: 0 | AF2: 0 | AG2: 45611.977 | AH2: -2 | AI2: -2 | AJ2: 716 | AK2: 846 | AL2: 643 | AM2: -2 | AN2: -2 | AO2: 1001 | AP2: -2 | AQ2: 1256 | AR2: 1150 | AS2: -2 | AT2: -2 | AU2: -2 | AV2: -2 | AW2: -2 | AX2: 2142 | AY2: 960 | AZ2: 1164 | BA2: -2 | BB2: -2 | BC2: -2 | BD2: -2 | BE2: -2 | BF2: -2 | BG2: -2 | BH2: -2 | BI2: -2
A3: businessornot.fr | B3: 22 | C3: develink | D3: 2135 | E3: 404 | F3: 10 | G3: 31 | H3: Society/Politics | I3: 13 | J3: 59 | K3: 327 | L3: 1594 | M3: 0 | N3: -1 | O3: Lancez votre projet digital : conseils, outils et stratégies pour entrepreneurs modernes | P3: 860 | Q3: 220 | R3: 139 | S3: 0 | T3: 0 | U3: fr,en | V3: fr,en,ru,th,de | W3: 7 | X3: 12832016 | Y3: 41 | Z3: 46 | AA3: 48 | AB3: fr | AC3: 0 | AD3: 0 | AE3: 0 | AF3: 0 | AG3: 46003.1 | AH3: 35 | AI3: 65 | AJ3: -2 | AK3: 22 | AL3: -2 | AM3: -2 | AN3: -2 | AO3: 31 | AP3: 50 | AQ3: -2 | AR3: -2 | AS3: -2 | AT3: -2 | AU3: -2 | AV3: -2 | AW3: -2 | AX3: -2 | AY3: -2 | AZ3: -2 | BA3: -2 | BB3: -2 | BC3: -2 | BD3: -2 | BE3: -2 | BF3: -2 | BG3: -2 | BH3: -2 | BI3: -2
A4: charlestech.fr | B4: 65 | C4: ereferer | D4: 668 | E4: 889 | F4: 18 | G4: 35 | H4: Regional/Europe | I4: 55 | J4: 30 | K4: 171 | L4: 201 | M4: 1 | N4: -1 | O4: Tests high-tech, comparatifs et promos | Charles Tech | P4: 8454 | Q4: 460 | R4: 342 | S4: 6 | T4: 0 | U4: fr,en | V4: en,fr,de,es,hu,nl,tr,pt,ru,it | W4: 18 | X4: 427434 | Y4: 70 | Z4: 825 | AA4: 1211 | AB4: fr | AC4: 0 | AD4: 0 | AE4: 0 | AF4: 0 | AG4: 45611.977 | AH4: 65 | AI4: 259 | AJ4: 182 | AK4: 357 | AL4: -2 | AM4: -2 | AN4: -2 | AO4: 358 | AP4: 269 | AQ4: 1405 | AR4: -2 | AS4: 405 | AT4: -2 | AU4: -2 | AV4: 340 | AW4: -2 | AX4: 794 | AY4: 466 | AZ4: 415 | BA4: 744 | BB4: 495 | BC4: 700 | BD4: 612 | BE4: -2 | BF4: 275 | BG4: -2 | BH4: 672 | BI4: 545
A5: digitiz.fr | B5: 257 | C5: ereferer | D5: 24483 | E5: 1254 | F5: 18 | G5: 36 | H5: Shopping/Consumer Electronics | I5: 67 | J5: 123 | K5: 615 | L5: 3036 | M5: 0 | N5: -1 | O5: Digitiz - Trouvez les bonnes solutions pour réussir sur le web | P5: 80292 | Q5: 722 | R5: 496 | S5: 9 | T5: 2 | U5: fr,en | V5: fr,en | W5: 14 | X5: 148471 | Y5: 149 | Z5: 846 | AA5: 1374 | AB5: fr | AC5: 30 | AD5: 40 | AE5: 31 | AF5: 32 | AG5: 45611.977 | AH5: 257 | AI5: 259 | AJ5: 288 | AK5: 343 | AL5: 339 | AM5: -2 | AN5: 569 | AO5: 353 | AP5: 344 | AQ5: -2 | AR5: 470 | AS5: 279 | AT5: -2 | AU5: 358 | AV5: 386 | AW5: -2 | AX5: -2 | AY5: 380 | AZ5: 321 | BA5: 688 | BB5: 540 | BC5: 930 | BD5: -2 | BE5: -2 | BF5: -2 | BG5: -2 | BH5: 760 | BI5: -2
A6: expertbanque.fr | B6: 39 | C6: whitepress | D6: 35 | E6: 19 | F6: 7 | G6: 21 | H6: Health/Professions | I6: 3 | J6: 0 | K6: 8 | L6: 33 | M6: 0 | N6: -1 | O6: Expert Banque : Guide Finance & Banque 2026 | Épargne, Crédit | P6: 21 | Q6: 15 | R6: 15 | S6: 0 | T6: 0 | U6: fr,en | V6: en,fr | W6: 4 | X6: 32897212 | Y6: 2 | Z6: 5 | AA6: 17 | AB6: fr | AC6: 0 | AD6: 0 | AE6: 0 | AF6: 0 | AG6: 46036.137 | AH6: -2 | AI6: -2 | AJ6: 39 | AK6: -2 | AL6: -2 | AM6: -2 | AN6: -2 | AO6: -2 | AP6: 47 | AQ6: -2 | AR6: -2 | AS6: -2 | AT6: -2 | AU6: -2 | AV6: -2 | AW6: -2 | AX6: -2 | AY6: -2 | AZ6: -2 | BA6: -2 | BB6: -2 | BC6: -2 | BD6: -2 | BE6: -2 | BF6: -2 | BG6: -2 | BH6: -2 | BI6: -2
A7: finance-heros.fr | B7: 2482 | C7: paperclub | D7: 128274 | E7: 3403 | F7: 39 | G7: 59 | H7: Business/Investing | I7: 73 | J7: 4198 | K7: 8635 | L7: 115863 | M7: 1 | N7: -1 | O7: Finance Héros | Prenez les bonnes décisions financières ! | P7: 657750 | Q7: 1948 | R7: 1042 | S7: 5 | T7: 0 | U7: fr,en | V7: fr,zh,en | W7: 24 | X7: 61290 | Y7: 1937 | Z7: 2865 | AA7: 2045 | AB7: fr | AC7: 53 | AD7: 62 | AE7: 129 | AF7: 33 | AG7: 45611.989 | AH7: -2 | AI7: -2 | AJ7: -2 | AK7: -2 | AL7: -2 | AM7: -2 | AN7: -2 | AO7: 2482 | AP7: -2 | AQ7: -2 | AR7: -2 | AS7: -2 | AT7: -2 | AU7: -2 | AV7: -2 | AW7: -2 | AX7: -2 | AY7: 2591 | AZ7: -2 | BA7: -2 | BB7: -2 | BC7: -2 | BD7: -2 | BE7: -2 | BF7: -2 | BG7: -2 | BH7: -2 | BI7: -2
A8: hdfever.fr | B8: 136 | C8: collaborator | D8: 178 | E8: 753 | F8: 30 | G8: 38 | H8: Business | I8: 40 | J8: 6 | K8: 78 | L8: 41 | M8: 0 | N8: -1 | O8: Accueil - HDFever | P8: 8880 | Q8: 457 | R8: 359 | S8: 2 | T8: 0 | U8: fr | V8: fr,en,bg,es,el,ru,de,da,pl,it | W8: 14 | X8: 1537877 | Y8: 22 | Z8: 81 | AA8: 144 | AB8: fr | AC8: 0 | AD8: 0 | AE8: 0 | AF8: 0 | AG8: 45611.977 | AH8: 139 | AI8: 181 | AJ8: 236 | AK8: 180 | AL8: -2 | AM8: -2 | AN8: 136 | AO8: 199 | AP8: 181 | AQ8: 218 | AR8: -2 | AS8: 161 | AT8: -2 | AU8: 209 | AV8: 290 | AW8: -2 | AX8: 298 | AY8: 252 | AZ8: 293 | BA8: 311 | BB8: 320 | BC8: 290 | BD8: -2 | BE8: 221 | BF8: 170 | BG8: 259 | BH8: 258 | BI8: 235
A9: infonet.fr | B9: 448 | C9: linkavista | D9: 62278 | E9: 2274 | F9: 27 | G9: 39 | H9: Business | I9: 73 | J9: 3285 | K9: 21369 | L9: 4202 | M9: 0 | N9: -1 | O9: Infonet : Kbis, RCS, SIRET/SIREN, bilan - Informations Légales | P9: 31821 | Q9: 1390 | R9: 768 | S9: 3 | T9: 0 | U9: fr,en | V9: fr,en,de,es | W9: 17 | X9: 60390 | Y9: 3128 | Z9: 7114 | AA9: 5904 | AB9: fr | AC9: 392 | AD9: 542 | AE9: 848 | AF9: 868 | AG9: 45808.133 | AH9: -2 | AI9: 448 | AJ9: -2 | AK9: 449 | AL9: -2 | AM9: -2 | AN9: -2 | AO9: 585 | AP9: -2 | AQ9: -2 | AR9: -2 | AS9: -2 | AT9: -2 | AU9: -2 | AV9: -2 | AW9: -2 | AX9: -2 | AY9: -2 | AZ9: -2 | BA9: -2 | BB9: 820 | BC9: -2 | BD9: -2 | BE9: -2 | BF9: -2 | BG9: -2 | BH9: -2 | BI9: -2
A10: infos-byz.com | B10: 447 | C10: paperclub | D10: 0 | E10: 31 | F10: 5 | G10: 13 | H10: Arts/Music | I10: 3 | J10: 0 | K10: 0 | L10: 0 | M10: 0 | N10: -1 | P10: 83 | Q10: 24 | R10: 24 | S10: 0 | T10: 0 | U10: fr | V10: fr,en | W10: 0 | X10: 34908380 | Y10: 0 | Z10: 0 | AA10: 0 | AC10: 0 | AD10: 0 | AE10: 0 | AF10: 0 | AG10: 46120.134 | AH10: -2 | AI10: -2 | AJ10: -2 | AK10: -2 | AL10: -2 | AM10: -2 | AN10: -2 | AO10: 447 | AP10: -2 | AQ10: -2 | AR10: -2 | AS10: -2 | AT10: -2 | AU10: -2 | AV10: -2 | AW10: -2 | AX10: -2 | AY10: -2 | AZ10: -2 | BA10: -2 | BB10: -2 | BC10: -2 | BD10: -2 | BE10: -2 | BF10: -2 | BG10: -2 | BH10: -2 | BI10: -2
A11: itsocial.fr | B11: 1042 | C11: whitepress | D11: 7945 | E11: 1583 | F11: 32 | G11: 46 | H11: Computers/Software/Operating Systems | I11: 71 | J11: 110 | K11: 610 | L11: 4623 | M11: 1 | N11: -1 | O11: Média des tendances & usages IT, Tech et Métiers - IT SOCIAL | P11: 155743 | Q11: 1056 | R11: 805 | S11: 5 | T11: 0 | U11: fr,en | V11: en,fr,es,zh,de,it | W11: 17 | X11: 79707 | Y11: 187 | Z11: 322 | AA11: 516 | AB11: fr | AC11: 0 | AD11: 0 | AE11: 0 | AF11: 0 | AG11: 45611.978 | AH11: -2 | AI11: -2 | AJ11: 1042 | AK11: -2 | AL11: -2 | AM11: -2 | AN11: -2 | AO11: 1232 | AP11: -2 | AQ11: 2105 | AR11: -2 | AS11: -2 | AT11: -2 | AU11: 1379 | AV11: -2 | AW11: -2 | AX11: -2 | AY11: 1593 | AZ11: 2125 | BA11: 1469 | BB11: 1280 | BC11: -2 | BD11: -2 | BE11: 1474 | BF11: -2 | BG11: -2 | BH11: 1736 | BI11: -2
A12: leparisien.fr | B12: 10099 | C12: 1ereplace | D12: 3943995 | E12: 52182 | F12: 72 | G12: 67 | H12: News/Newspapers | I12: 89 | J12: 52883 | K12: 172004 | L12: 536778 | M12: 1 | N12: -1 | O12: Actualités en direct et info en continu - Le Parisien | P12: 15232936 | Q12: 27028 | R12: 13347 | S12: 102 | T12: 16 | U12: fr | V12: fr,en,de,ko,pt,fa,ru | W12: 14 | X12: 1965 | Y12: 40688 | Z12: 61160 | AA12: 56741 | AB12: fr | AC12: 7 | AD12: 16 | AE12: 253 | AF12: 148 | AG12: 45612.116 | AH12: -2 | AI12: -2 | AJ12: -2 | AK12: -2 | AL12: -2 | AM12: -2 | AN12: -2 | AO12: -2 | AP12: -2 | AQ12: -2 | AR12: -2 | AS12: 10099 | AT12: -2 | AU12: -2 | AV12: 14400 | AW12: -2 | AX12: -2 | AY12: -2 | AZ12: -2 | BA12: -2 | BB12: -2 | BC12: -2 | BD12: -2 | BE12: -2 | BF12: -2 | BG12: -2 | BH12: -2 | BI12: -2
A13: leparticulier.lefigaro.fr | B13: 2250 | C13: 123media | D13: 29399 | E13: 3416 | F13: 26 | G13: 36 | H13: Science/Social Sciences | I13: 91 | J13: 628 | K13: 3049 | L13: 8727 | M13: 1 | N13: -1 | O13: Actualité juridique, patrimoniale et pratique - Le Particulier | P13: 272024 | Q13: 2099 | R13: 1345 | S13: 2 | T13: 1 | V13: fr,en | W13: 38 | X13: 999 | Y13: 990 | Z13: 2128 | AA13: 3626 | AB13: fr | AC13: 0 | AD13: 0 | AE13: 0 | AF13: 0 | AG13: 45983.049 | AH13: -2 | AI13: -2 | AJ13: -2 | AK13: -2 | AL13: -2 | AM13: -2 | AN13: -2 | AO13: -2 | AP13: -2 | AQ13: -2 | AR13: 2250 | AS13: -2 | AT13: -2 | AU13: -2 | AV13: -2 | AW13: -2 | AX13: -2 | AY13: -2 | AZ13: -2 | BA13: -2 | BB13: -2 | BC13: -2 | BD13: -2 | BE13: -2 | BF13: -2 | BG13: -2 | BH13: -2 | BI13: -2
A14: lepoint.fr | B14: 630 | C14: poprise | D14: 1016018 | E14: 33557 | F14: 62 | G14: 59 | H14: News/Magazines and E-zines | I14: 86 | J14: 14865 | K14: 55772 | L14: 251593 | M14: 1 | N14: -1 | O14: Santé - L'actualité Santé – Le Point | P14: 2280709 | Q14: 17989 | R14: 9396 | S14: 95 | T14: 17 | U14: fr | V14: fr,en,pt,de,it,es,ru,ar,nl | W14: 10 | X14: 3928 | Y14: 16232 | Z14: 27235 | AA14: 25495 | AB14: fr | AC14: 18 | AD14: 30 | AE14: 90 | AF14: 38 | AG14: 45611.98 | AH14: -2 | AI14: -2 | AJ14: -2 | AK14: 1356 | AL14: 630 | AM14: -2 | AN14: -2 | AO14: -2 | AP14: 862 | AQ14: 1905 | AR14: 1080 | AS14: 698 | AT14: 796 | AU14: -2 | AV14: -2 | AW14: -2 | AX14: 2783 | AY14: 1864 | AZ14: 6998 | BA14: -2 | BB14: 1055 | BC14: 1445 | BD14: -2 | BE14: -2 | BF14: -2 | BG14: -2 | BH14: -2 | BI14: -2
A15: lessentieldeleco.fr | B15: 264 | C15: linkavista | D15: 93952 | E15: 1607 | F15: 21 | G15: 44 | H15: Society/Politics | I15: 52 | J15: 2541 | K15: 4549 | L15: 5961 | M15: 1 | N15: -1 | O15: L'Essentiel de l'Éco - Toute l'information sur les entreprises | P15: 6995 | Q15: 1068 | R15: 526 | S15: 1 | T15: 1 | U15: fr,en | V15: fr,en,de,zh,nl,es,th,hr,it | W15: 23 | X15: 541309 | Y15: 905 | Z15: 1332 | AA15: 1714 | AB15: fr | AC15: 0 | AD15: 0 | AE15: 0 | AF15: 0 | AG15: 45723.099 | AH15: 355 | AI15: 264 | AJ15: 378 | AK15: 467 | AL15: -2 | AM15: -2 | AN15: -2 | AO15: 468 | AP15: -2 | AQ15: 380 | AR15: -2 | AS15: 265 | AT15: -2 | AU15: -2 | AV15: 528 | AW15: -2 | AX15: -2 | AY15: 350 | AZ15: 490 | BA15: 475 | BB15: 670 | BC15: -2 | BD15: 507 | BE15: -2 | BF15: -2 | BG15: -2 | BH15: 580 | BI15: 275
A16: logicielfrance.com | B16: 21 | C16: linkavista | D16: 80 | E16: 78 | F16: 4 | G16: 19 | H16: Business/Employment | I16: 7 | J16: 2 | K16: 11 | L16: 90 | M16: 0 | N16: -1 | P16: 549 | Q16: 38 | R16: 29 | S16: 0 | T16: 0 | V16: en,fr,ar | W16: 4 | X16: 22360008 | Y16: 4 | Z16: 11 | AA16: 0 | AB16: fr | AC16: 0 | AD16: 0 | AE16: 0 | AF16: 0 | AG16: 45913.146 | AH16: -2 | AI16: 21 | AJ16: -2 | AK16: -2 | AL16: -2 | AM16: -2 | AN16: -2 | AO16: 31 | AP16: -2 | AQ16: -2 | AR16: -2 | AS16: -2 | AT16: -2 | AU16: -2 | AV16: -2 | AW16: -2 | AX16: -2 | AY16: -2 | AZ16: -2 | BA16: -2 | BB16: -2 | BC16: -2 | BD16: -2 | BE16: -2 | BF16: -2 | BG16: -2 | BH16: -2 | BI16: -2
A17: meilleurcomptable.fr | B17: 48 | C17: linkavista | D17: 77 | E17: 74 | F17: 11 | G17: 24 | H17: Business | I17: 14 | J17: 3 | K17: 26 | L17: 68 | M17: 0 | N17: -1 | O17: Meilleur comptable : comparatif comptables, logiciels, comptes pro | P17: 3803 | Q17: 40 | R17: 37 | S17: 0 | T17: 0 | U17: fr,en | V17: fr,en | W17: 17 | X17: 11849265 | Y17: 12 | Z17: 25 | AA17: 12 | AB17: fr | AC17: 0 | AD17: 0 | AE17: 0 | AF17: 0 | AG17: 45935.038 | AH17: 50 | AI17: 48 | AJ17: -2 | AK17: 86 | AL17: -2 | AM17: -2 | AN17: -2 | AO17: -2 | AP17: -2 | AQ17: -2 | AR17: -2 | AS17: -2 | AT17: -2 | AU17: -2 | AV17: -2 | AW17: -2 | AX17: -2 | AY17: -2 | AZ17: -2 | BA17: -2 | BB17: -2 | BC17: -2 | BD17: -2 | BE17: -2 | BF17: -2 | BG17: -2 | BH17: -2 | BI17: -2
A18: mondetech.fr | B18: 315 | C18: bazoom | D18: 294 | E18: 321 | F18: 13 | G18: 36 | H18: Business | I18: 27 | J18: 9 | K18: 36 | L18: 56 | M18: 0 | N18: -1 | O18: MondeTech.fr - L'actualité tech et les innovations de demain | P18: 38079 | Q18: 181 | R18: 155 | S18: 0 | T18: 0 | U18: fr,en | V18: fr,en,zh | W18: 14 | X18: 4858598 | Y18: 9 | Z18: 84 | AA18: 103 | AB18: fr | AC18: 0 | AD18: 0 | AE18: 0 | AF18: 0 | AG18: 45647.103 | AH18: -2 | AI18: -2 | AJ18: -2 | AK18: -2 | AL18: -2 | AM18: -2 | AN18: -2 | AO18: -2 | AP18: -2 | AQ18: -2 | AR18: 380 | AS18: -2 | AT18: -2 | AU18: -2 | AV18: -2 | AW18: -2 | AX18: -2 | AY18: -2 | AZ18: -2 | BA18: 356 | BB18: 315 | BC18: -2 | BD18: -2 | BE18: -2 | BF18: -2 | BG18: -2 | BH18: -2 | BI18: -2
A19: moneyvox.fr | B19: 2431 | C19: paperclub | D19: 152892 | E19: 3975 | F19: 47 | G19: 61 | H19: Computers/Software | I19: 73 | J19: 3451 | K19: 15431 | L19: 92155 | M19: 1 | N19: -1 | O19: MoneyVox - Infos et comparatifs pour votre argent | P19: 202707 | Q19: 2384 | R19: 1502 | S19: 17 | T19: 1 | U19: fr | V19: fr,en | W19: 5 | X19: 56202 | Y19: 4365 | Z19: 5535 | AA19: 4495 | AB19: fr | AC19: 14 | AD19: 20 | AE19: 46 | AF19: 33 | AG19: 45904.133 | AH19: -2 | AI19: -2 | AJ19: -2 | AK19: -2 | AL19: -2 | AM19: -2 | AN19: -2 | AO19: 2431 | AP19: -2 | AQ19: -2 | AR19: -2 | AS19: -2 | AT19: -2 | AU19: -2 | AV19: -2 | AW19: -2 | AX19: -2 | AY19: -2 | AZ19: -2 | BA19: -2 | BB19: -2 | BC19: -2 | BD19: -2 | BE19: -2 | BF19: -2 | BG19: -2 | BH19: -2 | BI19: -2
A20: nos-comparateurs.fr | B20: 61 | C20: develink | D20: 242 | E20: 10 | F20: 8 | G20: 20 | H20: Recreation/Travel | I20: 12 | J20: 4 | K20: 18 | L20: 27 | M20: 0 | N20: -1 | O20: Accueil - Comparateurs produits et services | P20: 12 | Q20: 10 | R20: 7 | S20: 0 | T20: 0 | U20: fr,en | V20: fr | W20: 4 | X20: 13596456 | Y20: 18 | Z20: 7 | AA20: 3 | AB20: fr | AC20: 0 | AD20: 0 | AE20: 0 | AF20: 0 | AG20: 46038.098 | AH20: -2 | AI20: -2 | AJ20: -2 | AK20: 61 | AL20: -2 | AM20: -2 | AN20: -2 | AO20: 62 | AP20: -2 | AQ20: -2 | AR20: -2 | AS20: -2 | AT20: -2 | AU20: -2 | AV20: -2 | AW20: -2 | AX20: -2 | AY20: -2 | AZ20: -2 | BA20: -2 | BB20: -2 | BC20: -2 | BD20: -2 | BE20: -2 | BF20: -2 | BG20: -2 | BH20: -2 | BI20: -2
A21: perspectives-conseils.com | B21: 61 | C21: ereferer | D21: 377 | E21: 216 | F21: 10 | G21: 27 | H21: Business/Real Estate | I21: 32 | J21: 24 | K21: 93 | L21: 83 | M21: 0 | N21: -1 | O21: Perspectives Conseils | Cabinet d'experts-comptables dévoués | P21: 459 | Q21: 87 | R21: 79 | S21: 0 | T21: 0 | U21: fr | V21: en,fr,ar,es | W21: 13 | X21: 3223581 | Y21: 36 | Z21: 85 | AA21: 114 | AB21: fr | AC21: 0 | AD21: 0 | AE21: 0 | AF21: 0 | AG21: 45611.99 | AH21: 61 | AI21: -2 | AJ21: -2 | AK21: -2 | AL21: -2 | AM21: -2 | AN21: -2 | AO21: 154 | AP21: -2 | AQ21: -2 | AR21: -2 | AS21: -2 | AT21: -2 | AU21: -2 | AV21: -2 | AW21: -2 | AX21: -2 | AY21: -2 | AZ21: -2 | BA21: -2 | BB21: -2 | BC21: -2 | BD21: -2 | BE21: -2 | BF21: -2 | BG21: -2 | BH21: -2 | BI21: -2
A22: perspectives-retraite.com | B22: 93 | C22: ereferer | D22: 567 | E22: 41 | F22: 12 | G22: 26 | H22: Regional/Europe | I22: 30 | J22: 10 | K22: 107 | L22: 206 | M22: 0 | N22: -1 | O22: Perspectives Retraite | Cabinet conseil expert en retraite | P22: 278 | Q22: 22 | R22: 22 | S22: 0 | T22: 0 | U22: fr,en | V22: fr,en,ar,es | W22: 19 | X22: 3811831 | Y22: 44 | Z22: 78 | AA22: 63 | AB22: fr | AC22: 0 | AD22: 0 | AE22: 0 | AF22: 0 | AG22: 45611.99 | AH22: 93 | AI22: 170 | AJ22: -2 | AK22: -2 | AL22: -2 | AM22: -2 | AN22: -2 | AO22: 95 | AP22: -2 | AQ22: -2 | AR22: -2 | AS22: -2 | AT22: -2 | AU22: -2 | AV22: -2 | AW22: -2 | AX22: -2 | AY22: -2 | AZ22: -2 | BA22: -2 | BB22: -2 | BC22: -2 | BD22: -2 | BE22: -2 | BF22: -2 | BG22: -2 | BH22: -2 | BI22: -2
A23: pharrell.fr | B23: 91 | C23: whitepress | D23: 42 | E23: 895 | F23: 21 | G23: 38 | H23: Reference/Museums | I23: 19 | J23: 3 | K23: 20 | L23: 11 | M23: 0 | N23: -1 | O23: Pharrell Business — Le média des entrepreneurs, investisseurs et indépendants | P23: 1376 | Q23: 623 | R23: 482 | S23: 2 | T23: 2 | U23: fr | V23: fr,en,ko,ja,de,ru,fa,es,it,ar | W23: 14 | X23: 8647870 | Y23: 13 | Z23: 40 | AA23: 199 | AB23: fr | AC23: 0 | AD23: 0 | AE23: 0 | AF23: 0 | AG23: 45611.989 | AH23: 622 | AI23: 107 | AJ23: 91 | AK23: -2 | AL23: -2 | AM23: -2 | AN23: -2 | AO23: 108 | AP23: -2 | AQ23: 390 | AR23: -2 | AS23: -2 | AT23: -2 | AU23: -2 | AV23: -2 | AW23: -2 | AX23: -2 | AY23: -2 | AZ23: -2 | BA23: -2 | BB23: 415 | BC23: -2 | BD23: -2 | BE23: -2 | BF23: -2 | BG23: -2 | BH23: -2 | BI23: -2
A24: plateya.fr | B24: 508 | C24: ereferer | D24: 19014 | E24: 208 | F24: 10 | G24: 34 | H24: Business/Business Services | I24: 52 | J24: 624 | K24: 3009 | L24: 4670 | M24: 0 | N24: -1 | O24: Office managers et assistants administratifs en freelance - Plateya | P24: 1343 | Q24: 170 | R24: 143 | S24: 0 | T24: 0 | U24: fr,en,ru | V24: fr,en,it,es,ar,zh,de,pt | W24: 8 | X24: 555124 | Y24: 453 | Z24: 377 | AA24: 247 | AB24: fr | AC24: 0 | AD24: 0 | AE24: 0 | AF24: 0 | AG24: 45744.125 | AH24: 508 | AI24: 824 | AJ24: -2 | AK24: -2 | AL24: -2 | AM24: -2 | AN24: -2 | AO24: 693 | AP24: -2 | AQ24: -2 | AR24: -2 | AS24: -2 | AT24: -2 | AU24: -2 | AV24: 1018 | AW24: -2 | AX24: 643 | AY24: -2 | AZ24: -2 | BA24: 894 | BB24: 745 | BC24: -2 | BD24: -2 | BE24: -2 | BF24: -2 | BG24: -2 | BH24: -2 | BI24: -2
A25: reussir-dscg.com | B25: 30 | C25: ereferer | D25: 34 | E25: 25 | F25: 0 | G25: 27 | I25: 3 | J25: 6 | K25: 13 | L25: 7 | M25: 0 | N25: -1 | O25: Bienvenue sur Réussir-DCG-DSCG | P25: 60 | Q25: 15 | R25: 11 | S25: 0 | T25: 0 | U25: fr,en | V25: fr,en,ar,es | W25: 6 | X25: 33796267 | Y25: 4 | Z25: 15 | AA25: 12 | AB25: fr | AC25: 0 | AD25: 0 | AE25: 0 | AF25: 0 | AG25: 46025.129 | AH25: 30 | AI25: -2 | AJ25: -2 | AK25: -2 | AL25: -2 | AM25: -2 | AN25: -2 | AO25: -2 | AP25: -2 | AQ25: -2 | AR25: -2 | AS25: -2 | AT25: -2 | AU25: -2 | AV25: -2 | AW25: -2 | AX25: -2 | AY25: -2 | AZ25: -2 | BA25: -2 | BB25: -2 | BC25: -2 | BD25: -2 | BE25: -2 | BF25: -2 | BG25: -2 | BH25: -2 | BI25: -2
A26: tool-advisor.fr | B26: 1386 | C26: paperclub | D26: 66699 | E26: 1419 | F26: 20 | G26: 46 | H26: Computers/Companies | I26: 68 | J26: 1982 | K26: 5861 | L26: 70572 | M26: 0 | N26: -1 | O26: Tool Advisor | Comparaison et Analyses de Logiciels B2B | P26: 9034 | Q26: 932 | R26: 578 | S26: 1 | T26: 0 | U26: fr,en | V26: fr,en,de,es,it,pt | W26: 21 | X26: 125351 | Y26: 883 | Z26: 579 | AA26: 246 | AB26: fr | AC26: 0 | AD26: 0 | AE26: 0 | AF26: 0 | AG26: 45684.113 | AH26: -2 | AI26: -2 | AJ26: -2 | AK26: -2 | AL26: -2 | AM26: -2 | AN26: -2 | AO26: 1386 | AP26: -2 | AQ26: -2 | AR26: -2 | AS26: -2 | AT26: -2 | AU26: -2 | AV26: -2 | AW26: -2 | AX26: -2 | AY26: -2 | AZ26: -2 | BA26: -2 | BB26: -2 | BC26: -2 | BD26: -2 | BE26: -2 | BF26: -2 | BG26: 2310 | BH26: -2 | BI26: -2
A27: 1comptabilite.fr | B27: 55 | C27: ereferer | D27: 2 | E27: 158 | F27: 18 | G27: 29 | H27: Business/Financial Services | I27: 25 | J27: 0 | K27: 4 | L27: 1 | M27: 0 | N27: -1 | O27: 1comptabilite.fr : le site des professionnels de la comptabilité | P27: 353 | Q27: 123 | R27: 113 | S27: 0 | T27: 0 | U27: fr | V27: fr,en,ar,es | W27: 0 | X27: 6004245 | Y27: 0 | Z27: 4 | AA27: 23 | AB27: fr | AC27: 0 | AD27: 0 | AE27: 0 | AF27: 0 | AG27: 45785.146 | AH27: 55 | AI27: 87 | AJ27: -2 | AK27: -2 | AL27: -2 | AM27: -2 | AN27: -2 | AO27: -2 | AP27: -2 | AQ27: -2 | AR27: -2 | AS27: -2 | AT27: -2 | AU27: -2 | AV27: -2 | AW27: -2 | AX27: -2 | AY27: -2 | AZ27: -2 | BA27: -2 | BB27: -2 | BC27: -2 | BD27: -2 | BE27: -2 | BF27: -2 | BG27: -2 | BH27: -2 | BI27: -2
A28: appvizer.fr | B28: 4149 | C28: ereferer | D28: 83933 | E28: 2461 | F28: 21 | G28: 49 | H28: Regional/Europe | I28: 72 | J28: 3996 | K28: 10707 | L28: 82302 | M28: 0 | N28: -1 | O28: Appvizer | Média & Comparateur de Logiciels pour les Professionnels | P28: 168474 | Q28: 1484 | R28: 969 | S28: 7 | T28: 3 | U28: fr | V28: en,it,de,pt,fr,es | W28: 4 | X28: 66588 | Y28: 2571 | Z28: 4346 | AA28: 2800 | AB28: fr | AC28: 3 | AD28: 6 | AE28: 2 | AF28: 3 | AG28: 45810.646 | AH28: 4149 | AI28: -2 | AJ28: -2 | AK28: -2 | AL28: -2 | AM28: -2 | AN28: -2 | AO28: -2 | AP28: -2 | AQ28: -2 | AR28: -2 | AS28: -2 | AT28: -2 | AU28: -2 | AV28: -2 | AW28: -2 | AX28: -2 | AY28: -2 | AZ28: -2 | BA28: -2 | BB28: -2 | BC28: -2 | BD28: -2 | BE28: -2 | BF28: -2 | BG28: -2 | BH28: -2 | BI28: -2
A29: baticopro.com | B29: 1210 | C29: poprise | D29: 5454 | E29: 642 | F29: 17 | G29: 34 | H29: Home/Gardening | I29: 47 | J29: 213 | K29: 1230 | L29: 2219 | M29: 0 | N29: -1 | O29: Baticopro : tout pour les copropriétés : produits, lettres et guides conseils | P29: 16987 | Q29: 332 | R29: 281 | S29: 1 | T29: 0 | U29: fr | V29: fr,en | W29: 0 | X29: 840344 | Y29: 211 | Z29: 183 | AA29: 221 | AB29: fr | AC29: 0 | AD29: 0 | AE29: 0 | AF29: 0 | AG29: 45612.003 | AH29: -2 | AI29: -2 | AJ29: -2 | AK29: 1303 | AL29: 1210 | AM29: -2 | AN29: -2 | AO29: 1304 | AP29: -2 | AQ29: -2 | AR29: -2 | AS29: -2 | AT29: -2 | AU29: -2 | AV29: -2 | AW29: -2 | AX29: -2 | AY29: 1570 | AZ29: 3968 | BA29: -2 | BB29: -2 | BC29: -2 | BD29: -2 | BE29: -2 | BF29: -2 | BG29: -2 | BH29: -2 | BI29: -2
A30: beaboss.fr | B30: 694 | C30: ereferer | D30: 6467 | E30: 1727 | F30: 28 | G30: 43 | H30: Computers/News and Media | I30: 70 | J30: 454 | K30: 1638 | L30: 1939 | M30: 1 | N30: -1 | O30: Beaboss.fr le site des dirigeants de petites et moyennes entreprises le site des dirigeants de petites et moyennes entreprises - Beaboss.fr le site des dirigeants de petites et moyennes entreprises | P30: 98949 | Q30: 975 | R30: 716 | S30: 1 | T30: 0 | U30: fr,en | V30: fr,en | W30: 7 | X30: 112789 | Y30: 295 | Z30: 651 | AA30: 1092 | AB30: fr | AC30: 0 | AD30: 0 | AE30: 0 | AF30: 0 | AG30: 45612.003 | AH30: 694 | AI30: 1604 | AJ30: -2 | AK30: 955 | AL30: 796 | AM30: -2 | AN30: -2 | AO30: 795 | AP30: 1014 | AQ30: -2 | AR30: 1175 | AS30: 790 | AT30: -2 | AU30: -2 | AV30: 1764 | AW30: -2 | AX30: -2 | AY30: 956 | AZ30: 1763 | BA30: -2 | BB30: 1275 | BC30: 1150 | BD30: -2 | BE30: -2 | BF30: -2 | BG30: -2 | BH30: -2 | BI30: -2
A31: bfmtv.com | B31: 2000 | C31: 123media | D31: 13468748 | E31: 44300 | F31: 42 | G31: 67 | H31: Business/Investing | I31: 89 | J31: 67939 | K31: 238649 | L31: 1599579 | M31: 1 | N31: -1 | O31: Actualités en continu et info en direct et replay - BFM | P31: 20067689 | Q31: 23605 | R31: 11795 | S31: 76 | T31: 18 | U31: fr,en | V31: fr,en,de,ru | W31: 39 | X31: 1996 | Y31: 60864 | Z31: 83753 | AA31: 83768 | AB31: fr | AC31: 0 | AD31: 0 | AE31: 0 | AF31: 0 | AG31: 45611.983 | AH31: 3884 | AI31: -2 | AJ31: -2 | AK31: 2389 | AL31: 2230 | AM31: -2 | AN31: -2 | AO31: 2800 | AP31: 2832 | AQ31: 2100 | AR31: 2000 | AS31: 2390 | AT31: 2572 | AU31: -2 | AV31: -2 | AW31: -2 | AX31: -2 | AY31: 2300 | AZ31: 6928 | BA31: -2 | BB31: -2 | BC31: -2 | BD31: -2 | BE31: -2 | BF31: -2 | BG31: -2 | BH31: -2 | BI31: -2
A32: c2ic.net | B32: 30 | C32: linksclub | D32: 71 | E32: 164 | F32: 34 | G32: 30 | H32: Computers/Organizations | I32: 5 | J32: 3 | K32: 11 | L32: 81 | M32: 0 | N32: -1 | O32: C2ic Votre professionnel tech | P32: 482 | Q32: 57 | R32: 53 | S32: 0 | T32: 0 | U32: fr,en | V32: fr,en,pl | W32: 0 | X32: 26996814 | Y32: 9 | Z32: 13 | AA32: 24 | AB32: fr | AC32: 0 | AD32: 0 | AE32: 0 | AF32: 0 | AG32: 45684.868 | AH32: -2 | AI32: -2 | AJ32: -2 | AK32: -2 | AL32: -2 | AM32: 30 | AN32: -2 | AO32: -2 | AP32: -2 | AQ32: -2 | AR32: -2 | AS32: -2 | AT32: -2 | AU32: -2 | AV32: -2 | AW32: -2 | AX32: -2 | AY32: -2 | AZ32: -2 | BA32: -2 | BB32: -2 | BC32: -2 | BD32: -2 | BE32: -2 | BF32: -2 | BG32: -2 | BH32: -2 | BI32: -2
A33: cesdefrance.fr | B33: 198 | C33: 1ereplace | D33: 419 | E33: 340 | F33: 34 | G33: 35 | H33: Society/Government | I33: 41 | J33: 33 | K33: 67 | L33: 68 | M33: 1 | N33: -1 | O33: Citoyen en Slip : Les dessous de l'économie française | P33: 4245 | Q33: 258 | R33: 212 | S33: 1 | T33: 0 | U33: fr | V33: fr,en,zh | W33: 0 | X33: 1390518 | Y33: 15 | Z33: 138 | AA33: 845 | AB33: fr | AC33: 0 | AD33: 0 | AE33: 0 | AF33: 0 | AG33: 45612.008 | AH33: 204 | AI33: 199 | AJ33: -2 | AK33: -2 | AL33: -2 | AM33: -2 | AN33: -2 | AO33: 308 | AP33: -2 | AQ33: -2 | AR33: -2 | AS33: 198 | AT33: -2 | AU33: -2 | AV33: -2 | AW33: -2 | AX33: -2 | AY33: -2 | AZ33: -2 | BA33: 488 | BB33: -2 | BC33: 255 | BD33: -2 | BE33: -2 | BF33: -2 | BG33: -2 | BH33: -2 | BI33: -2
A34: codeas.net | B34: 30 | C34: linksclub | D34: 0 | E34: 42 | F34: 14 | G34: 27 | H34: Computers/Software/Retailers | I34: 1 | J34: 0 | K34: 0 | L34: 0 | M34: 0 | N34: -1 | O34: Codeas - Développement informatique | P34: 159 | Q34: 32 | R34: 28 | S34: 0 | T34: 0 | U34: fr | V34: fr,en | W34: 0 | X34: 45782593 | Y34: 1 | Z34: 0 | AA34: 7 | AC34: 0 | AD34: 0 | AE34: 0 | AF34: 0 | AG34: 45684.868 | AH34: -2 | AI34: -2 | AJ34: -2 | AK34: -2 | AL34: -2 | AM34: 30 | AN34: -2 | AO34: -2 | AP34: -2 | AQ34: -2 | AR34: -2 | AS34: -2 | AT34: -2 | AU34: -2 | AV34: -2 | AW34: -2 | AX34: -2 | AY34: -2 | AZ34: -2 | BA34: -2 | BB34: -2 | BC34: -2 | BD34: -2 | BE34: -2 | BF34: -2 | BG34: -2 | BH34: -2 | BI34: -2
A35: compta-facile.com | B35: 3215 | C35: prensalink | D35: 77157 | E35: 1205 | F35: 17 | G35: 46 | H35: Recreation/Travel | I35: 60 | J35: 5124 | K35: 4682 | L35: 16886 | M35: 0 | N35: -1 | O35: Compta Facile - La référence en comptabilité | P35: 9114 | Q35: 711 | R35: 537 | S35: 1 | T35: 0 | U35: fr,en | V35: fr,en,ar,th | W35: 0 | X35: 279651 | Y35: 454 | Z35: 419 | AA35: 289 | AB35: fr | AC35: 0 | AD35: 0 | AE35: 0 | AF35: 0 | AG35: 45612.003 | AH35: -2 | AI35: -2 | AJ35: -2 | AK35: -2 | AL35: -2 | AM35: -2 | AN35: -2 | AO35: 6653 | AP35: -2 | AQ35: -2 | AR35: -2 | AS35: -2 | AT35: -2 | AU35: -2 | AV35: -2 | AW35: -2 | AX35: -2 | AY35: 3215 | AZ35: 4656 | BA35: -2 | BB35: -2 | BC35: -2 | BD35: -2 | BE35: -2 | BF35: -2 | BG35: -2 | BH35: -2 | BI35: -2
A36: compta-online.com | B36: 930 | C36: ereferer | D36: 98229 | E36: 1828 | F36: 26 | G36: 41 | H36: Business | I36: 64 | J36: 7037 | K36: 10220 | L36: 25130 | M36: 1 | N36: -1 | O36: Compta Online, s'informer, partager, évoluer | P36: 58963 | Q36: 1015 | R36: 717 | S36: 3 | T36: 0 | U36: fr | V36: fr,en | W36: 4 | X36: 182295 | Y36: 1539 | Z36: 2099 | AA36: 1696 | AB36: fr | AC36: 0 | AD36: 0 | AE36: 0 | AF36: 0 | AG36: 45611.98 | AH36: 930 | AI36: -2 | AJ36: -2 | AK36: -2 | AL36: -2 | AM36: -2 | AN36: -2 | AO36: 2717 | AP36: -2 | AQ36: -2 | AR36: -2 | AS36: -2 | AT36: -2 | AU36: -2 | AV36: -2 | AW36: -2 | AX36: -2 | AY36: -2 | AZ36: 3554 | BA36: -2 | BB36: -2 | BC36: 1145 | BD36: -2 | BE36: -2 | BF36: -2 | BG36: -2 | BH36: -2 | BI36: -2
A37: comptareal.fr | B37: 16 | C37: ereferer | D37: 6 | E37: 169 | F37: 5 | G37: 25 | H37: Shopping/Vehicles | I37: 8 | J37: 0 | K37: 9 | L37: 0 | M37: 0 | N37: -1 | O37: Comptareal - | P37: 321 | Q37: 63 | R37: 57 | S37: 0 | T37: 0 | U37: fr,en | V37: fr,en,ru,th | W37: 4 | X37: 20080292 | Y37: 4 | Z37: 4 | AA37: 10 | AB37: fr | AC37: 0 | AD37: 0 | AE37: 0 | AF37: 0 | AG37: 46105.136 | AH37: 16 | AI37: -2 | AJ37: -2 | AK37: -2 | AL37: -2 | AM37: -2 | AN37: -2 | AO37: -2 | AP37: -2 | AQ37: -2 | AR37: -2 | AS37: -2 | AT37: -2 | AU37: -2 | AV37: -2 | AW37: -2 | AX37: -2 | AY37: -2 | AZ37: -2 | BA37: -2 | BB37: -2 | BC37: -2 | BD37: -2 | BE37: -2 | BF37: -2 | BG37: -2 | BH37: -2 | BI37: -2
A38: compte-pro.com | B38: 306 | C38: ereferer | D38: 2500 | E38: 1413 | F38: 30 | G38: 48 | H38: Business | I38: 70 | J38: 114 | K38: 669 | L38: 3287 | M38: 0 | N38: -1 | O38: Compte-pro.com : Comparateur de banques et logiciels pro en ligne | P38: 3538 | Q38: 875 | R38: 580 | S38: 0 | T38: 0 | U38: fr,en | V38: fr,en,it,es,de,th | W38: 5 | X38: 97890 | Y38: 237 | Z38: 735 | AA38: 1047 | AB38: fr | AC38: 0 | AD38: 0 | AE38: 0 | AF38: 0 | AG38: 45777.995 | AH38: 306 | AI38: -2 | AJ38: -2 | AK38: -2 | AL38: -2 | AM38: -2 | AN38: -2 | AO38: 493 | AP38: -2 | AQ38: -2 | AR38: -2 | AS38: 440 | AT38: -2 | AU38: -2 | AV38: -2 | AW38: -2 | AX38: -2 | AY38: -2 | AZ38: -2 | BA38: -2 | BB38: -2 | BC38: -2 | BD38: -2 | BE38: -2 | BF38: -2 | BG38: -2 | BH38: -2 | BI38: -2
A39: connectbanque.com | B39: 651 | C39: whitepress | D39: 23415 | E39: 866 | F39: 25 | G39: 45 | H39: Business/Financial Services | I39: 62 | J39: 831 | K39: 2741 | L39: 27115 | M39: 0 | N39: -1 | O39: 💳 Comparateur de banques en ligne et services bancaires | P39: 8289 | Q39: 576 | R39: 392 | S39: 1 | T39: 1 | U39: fr | V39: en,fr,ar,es | W39: 4 | X39: 226683 | Y39: 809 | Z39: 1146 | AA39: 844 | AB39: fr | AC39: 0 | AD39: 0 | AE39: 0 | AF39: 0 | AG39: 45612.009 | AH39: 695 | AI39: -2 | AJ39: 651 | AK39: 694 | AL39: 712 | AM39: -2 | AN39: 1075 | AO39: 1001 | AP39: 814 | AQ39: 1152 | AR39: -2 | AS39: -2 | AT39: -2 | AU39: 1129 | AV39: 1008 | AW39: -2 | AX39: -2 | AY39: 735 | AZ39: 1239 | BA39: -2 | BB39: -2 | BC39: 800 | BD39: -2 | BE39: 1210 | BF39: -2 | BG39: -2 | BH39: 1443 | BI39: 885
A40: crowdlending.fr | B40: 62 | C40: linkavista | D40: 1078 | E40: 356 | F40: 15 | G40: 37 | H40: Computers/Internet/Web Design and Development | I40: 37 | J40: 10 | K40: 73 | L40: 726 | M40: 0 | N40: -1 | O40: Comment mieux épargner ? | Crowdlending.fr | P40: 929 | Q40: 210 | R40: 190 | S40: 0 | T40: 0 | U40: fr,en | V40: fr,en,es,nl,no,de,id,ru,vi | W40: 4 | X40: 1941826 | Y40: 21 | Z40: 69 | AA40: 86 | AB40: fr | AC40: 0 | AD40: 0 | AE40: 0 | AF40: 0 | AG40: 45904.133 | AH40: 63 | AI40: 62 | AJ40: -2 | AK40: -2 | AL40: -2 | AM40: -2 | AN40: -2 | AO40: 92 | AP40: -2 | AQ40: -2 | AR40: -2 | AS40: -2 | AT40: -2 | AU40: -2 | AV40: -2 | AW40: -2 | AX40: -2 | AY40: -2 | AZ40: -2 | BA40: -2 | BB40: -2 | BC40: -2 | BD40: -2 | BE40: -2 | BF40: -2 | BG40: -2 | BH40: -2 | BI40: -2
...
