Workbook

Sheet LLM Brand Tracker (1)
A1: URL | B1: Nom de domaine | C1: LLMs | D1: Count | E1: Prompts | F1: Véoprint Cited | G1: prix Linkfinder
A2: https://www.mon-tote-bag.fr/tote-bag-personnalise/ | B2: =IFERROR(__xludf.DUMMYFUNCTION("REGEXREPLACE(A2, ""^https?://(www\.)?|/.*"", """")"),"mon-tote-bag.fr") -> mon-tote-bag.fr | C2: chatgpt | D2: 1 | E2: Meilleur site pour commander des tote bags personnalisés | F2: ❌ | G2: {=XLOOKUP(B2,Sheet1!A:A,Sheet1!B:B,"absent des plateformes")} -> 13
A3: https://www.mon-tote-bag.fr/ | B3: =IFERROR(__xludf.DUMMYFUNCTION("REGEXREPLACE(A3, ""^https?://(www\.)?|/.*"", """")"),"mon-tote-bag.fr") -> mon-tote-bag.fr | C3: chatgpt | D3: 1 | E3: Meilleur site pour commander des tote bags personnalisés | F3: ❌ | G3: {=XLOOKUP(B3,Sheet1!A:A,Sheet1!B:B,"absent des plateformes")} -> 13
A4: https://ecostart.fr/top-alternatives-a-vistaprint-trouvez-votre-imprimeur-en-ligne-ideal/ | B4: =IFERROR(__xludf.DUMMYFUNCTION("REGEXREPLACE(A4, ""^https?://(www\.)?|/.*"", """")"),"ecostart.fr") -> ecostart.fr | C4: chatgpt | D4: 1 | E4: Comparatif imprimeurs en ligne pas chers en France | F4: ✅ | G4: {=XLOOKUP(B4,Sheet1!A:A,Sheet1!B:B,"absent des plateformes")} -> 22
A5: https://www.reddit.com/r/france/comments/1p9vij4/o%C3%B9_faire_imprimer_des_prints_et_stickers/ | B5: =IFERROR(__xludf.DUMMYFUNCTION("REGEXREPLACE(A5, ""^https?://(www\.)?|/.*"", """")"),"reddit.com") -> reddit.com | C5: chatgpt | D5: 2 | E5: Comparatif imprimeurs en ligne pas chers en France | F5: ❌ | G5: {=XLOOKUP(B5,Sheet1!A:A,Sheet1!B:B,"absent des plateformes")} -> 29
A6: https://www.reddit.com/r/france/comments/iqtmd6 | B6: =IFERROR(__xludf.DUMMYFUNCTION("REGEXREPLACE(A6, ""^https?://(www\.)?|/.*"", """")"),"reddit.com") -> reddit.com | C6: chatgpt | D6: 2 | E6: Comparatif imprimeurs en ligne pas chers en France | F6: ❌ | G6: {=XLOOKUP(B6,Sheet1!A:A,Sheet1!B:B,"absent des plateformes")} -> 29
A7: https://www.reddit.com/r/AskFrance/comments/1piyd0o/faire_imprimer_un_poster/ | B7: =IFERROR(__xludf.DUMMYFUNCTION("REGEXREPLACE(A7, ""^https?://(www\.)?|/.*"", """")"),"reddit.com") -> reddit.com | C7: chatgpt | D7: 1 | E7: Comparatif imprimeurs en ligne pas chers en France | F7: ❌ | G7: {=XLOOKUP(B7,Sheet1!A:A,Sheet1!B:B,"absent des plateformes")} -> 29
A8: https://www.reddit.com/r/u_Proof_Discipline_108/comments/1qi1hbs/questce_quun_objet_promotionnel_et_publicitaire/ | B8: =IFERROR(__xludf.DUMMYFUNCTION("REGEXREPLACE(A8, ""^https?://(www\.)?|/.*"", """")"),"reddit.com") -> reddit.com | C8: chatgpt | D8: 1 | E8: Comment commander des goodies personnalisés pour un événement ? | F8: ❌ | G8: {=XLOOKUP(B8,Sheet1!A:A,Sheet1!B:B,"absent des plateformes")} -> 29
A9: https://entreprise-innov.fr/711/imprimeur-en-ligne-des-impressions-variees-a-prix-doux/ | B9: =IFERROR(__xludf.DUMMYFUNCTION("REGEXREPLACE(A9, ""^https?://(www\.)?|/.*"", """")"),"entreprise-innov.fr") -> entreprise-innov.fr | C9: chatgpt | D9: 2 | E9: Comparatif imprimeurs en ligne pas chers en FranceQuels sont les imprimeurs pour entreprises les mieux notés en France ? | F9: ❌ | G9: {=XLOOKUP(B9,Sheet1!A:A,Sheet1!B:B,"absent des plateformes")} -> 46
A10: https://www.outils-accessoires.fr/vos-documents-administratifs/imprimeur-en-ligne-lideal-pour-votre-projet.html | B10: =IFERROR(__xludf.DUMMYFUNCTION("REGEXREPLACE(A10, ""^https?://(www\.)?|/.*"", """")"),"outils-accessoires.fr") -> outils-accessoires.fr | C10: chatgpt | D10: 1 | E10: Comment choisir son imprimeur en ligne ? | F10: ❌ | G10: {=XLOOKUP(B10,Sheet1!A:A,Sheet1!B:B,"absent des plateformes")} -> 46
A11: https://startups-nation.fr/top-9-des-meilleurs-imprimeurs-en-ligne/ | B11: =IFERROR(__xludf.DUMMYFUNCTION("REGEXREPLACE(A11, ""^https?://(www\.)?|/.*"", """")"),"startups-nation.fr") -> startups-nation.fr | C11: chatgpt | D11: 3 | E11: Quels sont les imprimeurs pour entreprises les mieux notés en France ? | F11: ❌ | G11: {=XLOOKUP(B11,Sheet1!A:A,Sheet1!B:B,"absent des plateformes")} -> 49
A12: https://startups-nation.fr/veoprint-limprimeur-en-ligne-des-entreprises/ | B12: =IFERROR(__xludf.DUMMYFUNCTION("REGEXREPLACE(A12, ""^https?://(www\.)?|/.*"", """")"),"startups-nation.fr") -> startups-nation.fr | C12: chatgpt | D12: 2 | E12: Imprimeur en ligne pour PME et startups | F12: ✅ | G12: {=XLOOKUP(B12,Sheet1!A:A,Sheet1!B:B,"absent des plateformes")} -> 49
A13: https://startups-nation.fr/imprimer-livre-classement-meilleurs-imprimeurs/ | B13: =IFERROR(__xludf.DUMMYFUNCTION("REGEXREPLACE(A13, ""^https?://(www\.)?|/.*"", """")"),"startups-nation.fr") -> startups-nation.fr | C13: chatgpt | D13: 1 | E13: Quels sont les imprimeurs pour entreprises les mieux notés en France ? | F13: ❌ | G13: {=XLOOKUP(B13,Sheet1!A:A,Sheet1!B:B,"absent des plateformes")} -> 49
A14: https://www.europe-etiquettes.fr/print/imprimerie-ligne-professionnels-reussir-vos-etiquettes-personnalisees | B14: =IFERROR(__xludf.DUMMYFUNCTION("REGEXREPLACE(A14, ""^https?://(www\.)?|/.*"", """")"),"europe-etiquettes.fr") -> europe-etiquettes.fr | C14: chatgpt | D14: 1 | E14: Comment choisir son imprimeur en ligne ? | F14: ❌ | G14: {=XLOOKUP(B14,Sheet1!A:A,Sheet1!B:B,"absent des plateformes")} -> 50
A15: https://www.net67.fr/comparatif-saxoprint-analyse-detaillee-face-aux-geants-de-limpression-en-ligne/ | B15: =IFERROR(__xludf.DUMMYFUNCTION("REGEXREPLACE(A15, ""^https?://(www\.)?|/.*"", """")"),"net67.fr") -> net67.fr | C15: chatgpt | D15: 1 | E15: Comparatif imprimeurs en ligne pas chers en France | F15: ❌ | G15: {=XLOOKUP(B15,Sheet1!A:A,Sheet1!B:B,"absent des plateformes")} -> 50
A16: https://www.moovement.fr/prix-impression-cout-moyen-tarifs-et-comparatif-2025/ | B16: =IFERROR(__xludf.DUMMYFUNCTION("REGEXREPLACE(A16, ""^https?://(www\.)?|/.*"", """")"),"moovement.fr") -> moovement.fr | C16: chatgpt | D16: 1 | E16: Comparatif imprimeurs en ligne pas chers en France | F16: ❌ | G16: {=XLOOKUP(B16,Sheet1!A:A,Sheet1!B:B,"absent des plateformes")} -> 72
A17: https://babdp.org/top-services-dimprimerie-en-ligne-pour-professionnels-rapidite-et-excellence.php | B17: =IFERROR(__xludf.DUMMYFUNCTION("REGEXREPLACE(A17, ""^https?://(www\.)?|/.*"", """")"),"babdp.org") -> babdp.org | C17: chatgpt | D17: 1 | E17: Comparatif imprimeurs en ligne pas chers en France | F17: ❌ | G17: {=XLOOKUP(B17,Sheet1!A:A,Sheet1!B:B,"absent des plateformes")} -> 80
A18: https://pardotconsulting.fr/comment-choisir-un-meilleur-imprimeur-en-ligne/ | B18: =IFERROR(__xludf.DUMMYFUNCTION("REGEXREPLACE(A18, ""^https?://(www\.)?|/.*"", """")"),"pardotconsulting.fr") -> pardotconsulting.fr | C18: chatgpt | D18: 1 | E18: Comment choisir son imprimeur en ligne ? | F18: ❌ | G18: {=XLOOKUP(B18,Sheet1!A:A,Sheet1!B:B,"absent des plateformes")} -> 81
A19: https://aspekt.fr/creation-catalogue-produit-supports-print/ | B19: =IFERROR(__xludf.DUMMYFUNCTION("REGEXREPLACE(A19, ""^https?://(www\.)?|/.*"", """")"),"aspekt.fr") -> aspekt.fr | C19: chatgpt | D19: 1 | E19: Meilleur imprimeur pour des catalogues produits ? | F19: ❌ | G19: {=XLOOKUP(B19,Sheet1!A:A,Sheet1!B:B,"absent des plateformes")} -> 99
A20: https://cartonrecup.com/copytop-avis/ | B20: =IFERROR(__xludf.DUMMYFUNCTION("REGEXREPLACE(A20, ""^https?://(www\.)?|/.*"", """")"),"cartonrecup.com") -> cartonrecup.com | C20: chatgpt | D20: 1 | E20: Quel est le meilleur imprimeur en ligne pour des flyers ? | F20: ❌ | G20: {=XLOOKUP(B20,Sheet1!A:A,Sheet1!B:B,"absent des plateformes")} -> 145
A21: https://www.24presse.com/communique-de-presse/internet/realisaprint_propose_aux_professionnels_des_arts_graphiques_un_tableau_comparatif_des_principaux_imprimeurs_online_9917361/ | B21: =IFERROR(__xludf.DUMMYFUNCTION("REGEXREPLACE(A21, ""^https?://(www\.)?|/.*"", """")"),"24presse.com") -> 24presse.com | C21: chatgpt | D21: 1 | E21: Comparatif imprimeurs en ligne pas chers en France | F21: ❌ | G21: {=XLOOKUP(B21,Sheet1!A:A,Sheet1!B:B,"absent des plateformes")} -> 195
A22: https://digitiz.fr/outil/onlineprinters/ | B22: =IFERROR(__xludf.DUMMYFUNCTION("REGEXREPLACE(A22, ""^https?://(www\.)?|/.*"", """")"),"digitiz.fr") -> digitiz.fr | C22: chatgpt | D22: 2 | E22: Comparatif imprimeurs en ligne pas chers en FranceQuel est le meilleur imprimeur en ligne pour des flyers ? | F22: ✅ | G22: {=XLOOKUP(B22,Sheet1!A:A,Sheet1!B:B,"absent des plateformes")} -> 257
A23: https://digitiz.fr/blog/imprimeurs-en-ligne/ | B23: =IFERROR(__xludf.DUMMYFUNCTION("REGEXREPLACE(A23, ""^https?://(www\.)?|/.*"", """")"),"digitiz.fr") -> digitiz.fr | C23: chatgpt | D23: 2 | E23: Quels sont les imprimeurs pour entreprises les mieux notés en France ? | F23: ✅ | G23: {=XLOOKUP(B23,Sheet1!A:A,Sheet1!B:B,"absent des plateformes")} -> 257
A24: https://digitiz.fr/outil/exaprint/ | B24: =IFERROR(__xludf.DUMMYFUNCTION("REGEXREPLACE(A24, ""^https?://(www\.)?|/.*"", """")"),"digitiz.fr") -> digitiz.fr | C24: chatgpt | D24: 1 | E24: Comparatif imprimeurs en ligne pas chers en France | F24: ✅ | G24: {=XLOOKUP(B24,Sheet1!A:A,Sheet1!B:B,"absent des plateformes")} -> 257
A25: https://www.pme-web.com/criteres-imprimerie-en-ligne/ | B25: =IFERROR(__xludf.DUMMYFUNCTION("REGEXREPLACE(A25, ""^https?://(www\.)?|/.*"", """")"),"pme-web.com") -> pme-web.com | C25: chatgpt | D25: 1 | E25: Comment choisir son imprimeur en ligne ? | F25: ❌ | G25: {=XLOOKUP(B25,Sheet1!A:A,Sheet1!B:B,"absent des plateformes")} -> 374
A26: https://fr.bepub.com/annuaire-imprimerie/imprimeurs/printoclock-imprimerie-en-ligne | B26: =IFERROR(__xludf.DUMMYFUNCTION("REGEXREPLACE(A26, ""^https?://(www\.)?|/.*"", """")"),"fr.bepub.com") -> fr.bepub.com | C26: chatgpt | D26: 2 | E26: Comparatif imprimeurs en ligne pas chers en France | F26: ❌ | G26: {=XLOOKUP(B26,Sheet1!A:A,Sheet1!B:B,"absent des plateformes")} -> 736
A27: https://www.europages.fr/entreprises/france/imprimeur.html | B27: =IFERROR(__xludf.DUMMYFUNCTION("REGEXREPLACE(A27, ""^https?://(www\.)?|/.*"", """")"),"europages.fr") -> europages.fr | C27: chatgpt | D27: 2 | E27: Quels sont les imprimeurs pour entreprises les mieux notés en France ? | F27: ❌ | G27: {=XLOOKUP(B27,Sheet1!A:A,Sheet1!B:B,"absent des plateformes")} -> 1054
A28: https://www.latribune.fr/entreprises/2023-04-21/printoclock-prospere-dans-l-impression-et-s-ouvre-a-l-edition-958372.html | B28: =IFERROR(__xludf.DUMMYFUNCTION("REGEXREPLACE(A28, ""^https?://(www\.)?|/.*"", """")"),"latribune.fr") -> latribune.fr | C28: chatgpt | D28: 1 | E28: Comparatif imprimeurs en ligne pas chers en France | F28: ❌ | G28: {=XLOOKUP(B28,Sheet1!A:A,Sheet1!B:B,"absent des plateformes")} -> 1318
A29: https://www.lemonde.fr/emploi/article/2025/09/01/c-est-un-metier-les-imprimeurs-presses-de-repenser-leur-activite_6637979_1698637.html | B29: =IFERROR(__xludf.DUMMYFUNCTION("REGEXREPLACE(A29, ""^https?://(www\.)?|/.*"", """")"),"lemonde.fr") -> lemonde.fr | C29: chatgpt | D29: 1 | E29: Quels sont les imprimeurs pour entreprises les mieux notés en France ? | F29: ❌ | G29: {=XLOOKUP(B29,Sheet1!A:A,Sheet1!B:B,"absent des plateformes")} -> 12500
A30: https://www.easyflyer.fr/ | B30: =IFERROR(__xludf.DUMMYFUNCTION("REGEXREPLACE(A30, ""^https?://(www\.)?|/.*"", """")"),"easyflyer.fr") -> easyflyer.fr | C30: chatgpt | D30: 4 | E30: Quel imprimeur en ligne propose des devis personnalisés rapidement ?Imprimeur en ligne pour PME et startups | F30: ❌ | G30: {=XLOOKUP(B30,Sheet1!A:A,Sheet1!B:B,"absent des plateformes")} -> absent des plateformes
A31: https://www.123imprim.com/ | B31: =IFERROR(__xludf.DUMMYFUNCTION("REGEXREPLACE(A31, ""^https?://(www\.)?|/.*"", """")"),"123imprim.com") -> 123imprim.com | C31: chatgpt | D31: 4 | E31: Quel imprimeur en ligne propose des devis personnalisés rapidement ?Imprimeur en ligne pour PME et startups | F31: ❌ | G31: {=XLOOKUP(B31,Sheet1!A:A,Sheet1!B:B,"absent des plateformes")} -> absent des plateformes
A32: https://www.papeo.fr/imprimeur-en-ligne | B32: =IFERROR(__xludf.DUMMYFUNCTION("REGEXREPLACE(A32, ""^https?://(www\.)?|/.*"", """")"),"papeo.fr") -> papeo.fr | C32: chatgpt | D32: 4 | E32: Quel imprimeur en ligne propose des devis personnalisés rapidement ?Imprimeur en ligne pour PME et startups | F32: ❌ | G32: {=XLOOKUP(B32,Sheet1!A:A,Sheet1!B:B,"absent des plateformes")} -> absent des plateformes
A33: https://blog.veoprint.com/veoprint-qui-sommes-nous/ | B33: =IFERROR(__xludf.DUMMYFUNCTION("REGEXREPLACE(A33, ""^https?://(www\.)?|/.*"", """")"),"blog.veoprint.com") -> blog.veoprint.com | C33: chatgpt | D33: 3 | E33: Imprimeur en ligne pour PME et startups | F33: ✅ | G33: {=XLOOKUP(B33,Sheet1!A:A,Sheet1!B:B,"absent des plateformes")} -> absent des plateformes
A34: https://www.helloprint.fr/stylo-personnalise | B34: =IFERROR(__xludf.DUMMYFUNCTION("REGEXREPLACE(A34, ""^https?://(www\.)?|/.*"", """")"),"helloprint.fr") -> helloprint.fr | C34: chatgpt | D34: 3 | E34: Où acheter des stylos personnalisés avec logo entreprise ? | F34: ❌ | G34: {=XLOOKUP(B34,Sheet1!A:A,Sheet1!B:B,"absent des plateformes")} -> absent des plateformes
A35: https://www.bagart.fr/ | B35: =IFERROR(__xludf.DUMMYFUNCTION("REGEXREPLACE(A35, ""^https?://(www\.)?|/.*"", """")"),"bagart.fr") -> bagart.fr | C35: chatgpt | D35: 3 | E35: Meilleur site pour commander des tote bags personnalisésComment commander des goodies personnalisés pour un événement ? | F35: ❌ | G35: {=XLOOKUP(B35,Sheet1!A:A,Sheet1!B:B,"absent des plateformes")} -> absent des plateformes
A36: https://imprimeurs.nosavis.com/ | B36: =IFERROR(__xludf.DUMMYFUNCTION("REGEXREPLACE(A36, ""^https?://(www\.)?|/.*"", """")"),"imprimeurs.nosavis.com") -> imprimeurs.nosavis.com | C36: chatgpt | D36: 3 | E36: Quels sont les imprimeurs pour entreprises les mieux notés en France ? | F36: ❌ | G36: {=XLOOKUP(B36,Sheet1!A:A,Sheet1!B:B,"absent des plateformes")} -> absent des plateformes
A37: https://blog.copees.com/copees-vs-vistaprint-exaprint-et-realisaprint-le-comparatif-sans-langue-de-bois/ | B37: =IFERROR(__xludf.DUMMYFUNCTION("REGEXREPLACE(A37, ""^https?://(www\.)?|/.*"", """")"),"blog.copees.com") -> blog.copees.com | C37: chatgpt | D37: 3 | E37: Comparatif imprimeurs en ligne pas chers en France | F37: ❌ | G37: {=XLOOKUP(B37,Sheet1!A:A,Sheet1!B:B,"absent des plateformes")} -> absent des plateformes
A38: https://blog.copees.com/top-10-des-imprimeurs-les-plus-rapides-en-france/ | B38: =IFERROR(__xludf.DUMMYFUNCTION("REGEXREPLACE(A38, ""^https?://(www\.)?|/.*"", """")"),"blog.copees.com") -> blog.copees.com | C38: chatgpt | D38: 3 | E38: Quels sont les imprimeurs pour entreprises les mieux notés en France ? | F38: ❌ | G38: {=XLOOKUP(B38,Sheet1!A:A,Sheet1!B:B,"absent des plateformes")} -> absent des plateformes
A39: https://blog.copees.com/top-5-des-imprimeurs-eco-responsables-en-france/ | B39: =IFERROR(__xludf.DUMMYFUNCTION("REGEXREPLACE(A39, ""^https?://(www\.)?|/.*"", """")"),"blog.copees.com") -> blog.copees.com | C39: chatgpt | D39: 3 | E39: Quels sont les imprimeurs pour entreprises les mieux notés en France ? | F39: ❌ | G39: {=XLOOKUP(B39,Sheet1!A:A,Sheet1!B:B,"absent des plateformes")} -> absent des plateformes
A40: https://fr.wikipedia.org/wiki/Escourbiac | B40: =IFERROR(__xludf.DUMMYFUNCTION("REGEXREPLACE(A40, ""^https?://(www\.)?|/.*"", """")"),"fr.wikipedia.org") -> fr.wikipedia.org | C40: chatgpt | D40: 3 | E40: Quels sont les imprimeurs pour entreprises les mieux notés en France ? | F40: ❌ | G40: {=XLOOKUP(B40,Sheet1!A:A,Sheet1!B:B,"absent des plateformes")} -> absent des plateformes
...

Sheet Sheet1
A1: Domain | B1: Meilleur Prix | C1: Best_price | D1: Traffic | E1: RD | F1: TF | G1: CF | H1: TTF | I1: DR | J1: Top 3 Kws | K1: Top 4-10 Kws | L1: Traffic Value | M1: Gnews | N1: LF Value | O1: Title | P1: Backlinks | Q1: Ref Ips | R1: Ref Subnets | S1: Ref Edu | T1: Ref Gov | U1: Languages | V1: Ref Languages | W1: UR | X1: AR | Y1: Top 11-20 Kws | Z1: Top 21-50 Kws | AA1: Top 51+ Kws | AB1: Top Location | AC1: Paid Kws | AD1: Ads Count | AE1: Paid Traffic | AF1: Paid Traffic Cost | AG1: Date D'ajout | AH1: Ereferer | AI1: Linkavista | AJ1: Whitepress | AK1: Develink | AL1: Poprise | AM1: Linksclub | AN1: Collaborator | AO1: Paperclub | AP1: Soumettre | AQ1: Mistergoodlink | AR1: 123media | AS1: 1ereplace | AT1: Linkpublishers | AU1: Growwer | AV1: Unancor | AW1: Linkbroker | AX1: Prensalink | AY1: Prnews | AZ1: Backlinked | BA1: Bazoom | BB1: Purolink | BC1: Motherlink | BD1: Guestpostlinks | BE1: Prposting | BF1: Publisuites | BG1: Meup | BH1: Getalink
A2: 24presse.com | B2: 195 | C2: whitepress | D2: 2235 | E2: 572 | F2: 14 | G2: 39 | H2: Shopping/Food | I2: 50 | J2: 87 | K2: 276 | L2: 796 | M2: 1 | N2: -1 | O2: 24presse – You've got news, we've got medias | P2: 4464 | Q2: 368 | R2: 305 | S2: 1 | T2: 0 | U2: fr,en,de,es,nl,it | V2: fr,en,vi,zh,de,ru,es | W2: 0 | X2: 662052 | Y2: 56 | Z2: 76 | AA2: 56 | AB2: fr | AC2: 0 | AD2: 0 | AE2: 0 | AF2: 0 | AG2: 45611.979 | AH2: 394 | AI2: 319 | AJ2: 195 | AK2: -2 | AL2: -2 | AM2: -2 | AN2: 250 | AO2: 539 | AP2: -2 | AQ2: 369 | AR2: -2 | AS2: -2 | AT2: 222 | AU2: 311 | AV2: -2 | AW2: -2 | AX2: -2 | AY2: -2 | AZ2: 519 | BA2: 455 | BB2: 310 | BC2: -2 | BD2: -2 | BE2: -2 | BF2: 250 | BG2: 390 | BH2: 260
A3: aspekt.fr | B3: 99 | C3: linkavista | D3: 169 | E3: 225 | F3: 23 | G3: 34 | H3: Reference/Museums | I3: 29 | J3: 15 | K3: 119 | L3: 37 | M3: 0 | N3: -1 | O3: Anne Sophie Thomas - Experte Stratégie Digitale | Aspekt | P3: 7227 | Q3: 110 | R3: 91 | S3: 1 | T3: 0 | U3: fr | V3: fr,en | W3: 26 | X3: 4214213 | Y3: 14 | Z3: 145 | AA3: 226 | AB3: fr | AC3: 0 | AD3: 0 | AE3: 0 | AF3: 0 | AG3: 45611.977 | AH3: 125 | AI3: 99 | AJ3: 163 | AK3: 184 | AL3: -2 | AM3: -2 | AN3: -2 | AO3: 231 | AP3: 185 | AQ3: 165 | AR3: -2 | AS3: -2 | AT3: 357 | AU3: 206 | AV3: -2 | AW3: 954 | AX3: 270 | AY3: 220 | AZ3: 288 | BA3: 235 | BB3: 100 | BC3: 321 | BD3: 214 | BE3: 405 | BF3: 250 | BG3: 265 | BH3: -2
A4: babdp.org | B4: 80 | C4: paperclub | D4: 2 | E4: 242 | F4: 15 | G4: 34 | H4: Society/Issues | I4: 20 | J4: 0 | K4: 5 | L4: 0 | M4: 0 | N4: -1 | O4: Babdp - L'information au quotidien, pour tous | P4: 317 | Q4: 113 | R4: 99 | S4: 0 | T4: 0 | U4: fr | V4: fr,en,de,pt | W4: 4 | X4: 8029097 | Y4: 0 | Z4: 0 | AA4: 5 | AB4: fr | AC4: 0 | AD4: 0 | AE4: 0 | AF4: 0 | AG4: 46004.133 | AH4: -2 | AI4: -2 | AJ4: -2 | AK4: -2 | AL4: -2 | AM4: -2 | AN4: -2 | AO4: 80 | AP4: -2 | AQ4: -2 | AR4: -2 | AS4: -2 | AT4: -2 | AU4: -2 | AV4: -2 | AW4: -2 | AX4: -2 | AY4: -2 | AZ4: -2 | BA4: -2 | BB4: -2 | BC4: -2 | BD4: -2 | BE4: -2 | BF4: -2 | BG4: -2 | BH4: -2
A5: cartonrecup.com | B5: 145 | C5: linkavista | D5: 140 | E5: 36 | F5: 11 | G5: 28 | H5: Regional/Europe | I5: 9 | J5: 11 | K5: 23 | L5: 12 | M5: 0 | N5: -1 | O5: Tout savoir sur le Meuble en Carton | Conseils Pratiques en images | P5: 102 | Q5: 35 | R5: 30 | S5: 0 | T5: 0 | U5: fr,en,la | V5: fr,en | W5: 7 | X5: 18280632 | Y5: 2 | Z5: 4 | AA5: 1 | AB5: fr | AC5: 0 | AD5: 0 | AE5: 0 | AF5: 0 | AG5: 45679.71 | AH5: -2 | AI5: 145 | AJ5: -2 | AK5: -2 | AL5: -2 | AM5: -2 | AN5: -2 | AO5: -2 | AP5: -2 | AQ5: -2 | AR5: -2 | AS5: -2 | AT5: -2 | AU5: -2 | AV5: -2 | AW5: -2 | AX5: -2 | AY5: -2 | AZ5: -2 | BA5: -2 | BB5: -2 | BC5: -2 | BD5: -2 | BE5: -2 | BF5: -2 | BG5: -2 | BH5: -2
A6: digitiz.fr | B6: 257 | C6: ereferer | D6: 24483 | E6: 1254 | F6: 18 | G6: 36 | H6: Shopping/Consumer Electronics | I6: 67 | J6: 123 | K6: 615 | L6: 3036 | M6: 0 | N6: -1 | O6: Digitiz - Trouvez les bonnes solutions pour réussir sur le web | P6: 80292 | Q6: 722 | R6: 496 | S6: 9 | T6: 2 | U6: fr,en | V6: fr,en | W6: 14 | X6: 148471 | Y6: 149 | Z6: 846 | AA6: 1374 | AB6: fr | AC6: 30 | AD6: 40 | AE6: 31 | AF6: 32 | AG6: 45611.977 | AH6: 257 | AI6: 259 | AJ6: 288 | AK6: 343 | AL6: 339 | AM6: -2 | AN6: 569 | AO6: 353 | AP6: 344 | AQ6: -2 | AR6: 470 | AS6: 279 | AT6: 358 | AU6: 386 | AV6: -2 | AW6: -2 | AX6: 380 | AY6: 321 | AZ6: 688 | BA6: 540 | BB6: 930 | BC6: -2 | BD6: -2 | BE6: -2 | BF6: -2 | BG6: 760 | BH6: -2
A7: ecostart.fr | B7: 22 | C7: linkavista | D7: 17 | E7: 126 | F7: 25 | G7: 41 | H7: Society/Politics | I7: 26 | J7: 0 | K7: 8 | L7: 2 | M7: 0 | N7: -1 | O7: Ecostart - Lancez-vous ! | P7: 451 | Q7: 84 | R7: 66 | S7: 0 | T7: 0 | U7: fr | V7: fr,en | W7: 5 | X7: 5792052 | Y7: 1 | Z7: 9 | AA7: 19 | AB7: fr | AC7: 0 | AD7: 0 | AE7: 0 | AF7: 0 | AG7: 45611.977 | AH7: 23 | AI7: 22 | AJ7: 72 | AK7: -2 | AL7: 87 | AM7: -2 | AN7: -2 | AO7: 108 | AP7: -2 | AQ7: -2 | AR7: -2 | AS7: -2 | AT7: -2 | AU7: -2 | AV7: -2 | AW7: -2 | AX7: -2 | AY7: -2 | AZ7: -2 | BA7: 215 | BB7: -2 | BC7: -2 | BD7: -2 | BE7: -2 | BF7: -2 | BG7: -2 | BH7: -2
A8: entreprise-innov.fr | B8: 46 | C8: paperclub | D8: 0 | E8: 101 | F8: 18 | G8: 33 | H8: Business | I8: 0 | J8: 0 | K8: 0 | L8: 0 | M8: 0 | N8: -1 | O8: Entreprise Innov - L'information business qui fait avancer les entrepreneurs | P8: 165 | Q8: 82 | R8: 74 | S8: 0 | T8: 0 | U8: fr | V8: fr,en,de,lv,no,tr | W8: 4 | X8: 75057132 | Y8: 1 | Z8: 0 | AA8: 8 | AC8: 0 | AD8: 0 | AE8: 0 | AF8: 0 | AG8: 46107.134 | AH8: -2 | AI8: -2 | AJ8: -2 | AK8: -2 | AL8: -2 | AM8: -2 | AN8: -2 | AO8: 46 | AP8: -2 | AQ8: -2 | AR8: -2 | AS8: -2 | AT8: -2 | AU8: -2 | AV8: -2 | AW8: -2 | AX8: -2 | AY8: -2 | AZ8: -2 | BA8: -2 | BB8: -2 | BC8: -2 | BD8: -2 | BE8: -2 | BF8: -2 | BG8: -2 | BH8: -2
A9: europages.fr | B9: 1054 | C9: linkavista | D9: 23520 | E9: 1514 | F9: 26 | G9: 31 | H9: Business/Directories | I9: 62 | J9: 1055 | K9: 5673 | L9: 9278 | M9: 0 | N9: -1 | O9: europages France – Marché Fournisseurs & Grossistes B2B | P9: 58645 | Q9: 891 | R9: 653 | S9: 6 | T9: 0 | U9: fr | V9: fr,en,de,nl,it,es,da | W9: 4 | X9: 223014 | Y9: 1198 | Z9: 1522 | AA9: 1683 | AB9: fr | AC9: 0 | AD9: 0 | AE9: 0 | AF9: 0 | AG9: 45611.98 | AH9: -2 | AI9: 1054 | AJ9: -2 | AK9: -2 | AL9: -2 | AM9: -2 | AN9: -2 | AO9: -2 | AP9: -2 | AQ9: -2 | AR9: -2 | AS9: -2 | AT9: -2 | AU9: -2 | AV9: -2 | AW9: 1092 | AX9: -2 | AY9: -2 | AZ9: 1200 | BA9: -2 | BB9: -2 | BC9: -2 | BD9: -2 | BE9: -2 | BF9: -2 | BG9: -2 | BH9: -2
A10: europe-etiquettes.fr | B10: 50 | C10: linkavista | D10: 1225 | E10: 197 | F10: 27 | G10: 34 | H10: Home | I10: 8 | J10: 58 | K10: 277 | L10: 469 | M10: 0 | N10: -1 | O10: www.europe-etiquettes.fr | P10: 375 | Q10: 100 | R10: 96 | S10: 0 | T10: 0 | U10: fr | V10: fr,en,nl,de,it,pt,es,ja,ru,sv | W10: 12 | X10: 19723967 | Y10: 69 | Z10: 105 | AA10: 126 | AB10: fr | AC10: 0 | AD10: 0 | AE10: 0 | AF10: 0 | AG10: 45831.148 | AH10: 82 | AI10: 50 | AJ10: 91 | AK10: 81 | AL10: -2 | AM10: -2 | AN10: -2 | AO10: 85 | AP10: 89 | AQ10: -2 | AR10: -2 | AS10: -2 | AT10: -2 | AU10: -2 | AV10: -2 | AW10: 271 | AX10: -2 | AY10: -2 | AZ10: 288 | BA10: -2 | BB10: -2 | BC10: -2 | BD10: -2 | BE10: -2 | BF10: -2 | BG10: -2 | BH10: -2
A11: fr.bepub.com | B11: 736 | C11: develink | D11: 9 | E11: 93 | F11: 14 | G11: 14 | H11: Business | I11: 44 | J11: 2 | K11: 5 | L11: 0 | M11: 1 | N11: -1 | P11: 1348 | Q11: 77 | R11: 71 | S11: 0 | T11: 0 | U11: fr | V11: fr,en,nl | W11: 25 | X11: 1071197 | Y11: 0 | Z11: 1 | AA11: 0 | AB11: be | AC11: 0 | AD11: 0 | AE11: 0 | AF11: 0 | AG11: 45786.097 | AH11: -2 | AI11: -2 | AJ11: -2 | AK11: 736 | AL11: -2 | AM11: -2 | AN11: -2 | AO11: -2 | AP11: -2 | AQ11: -2 | AR11: -2 | AS11: -2 | AT11: -2 | AU11: -2 | AV11: -2 | AW11: -2 | AX11: 831 | AY11: -2 | AZ11: -2 | BA11: -2 | BB11: -2 | BC11: -2 | BD11: -2 | BE11: -2 | BF11: -2 | BG11: -2 | BH11: -2
A12: latribune.fr | B12: 1318 | C12: poprise | D12: 226982 | E12: 23381 | F12: 55 | G12: 58 | H12: News/Newspapers | I12: 84 | J12: 2982 | K12: 12610 | L12: 28808 | M12: 1 | N12: -1 | O12: La Tribune - Actualité Économique et Financière | P12: 1601142 | Q12: 12966 | R12: 7209 | S12: 46 | T12: 9 | U12: fr | V12: fr,en,de,es,ru,it,ar,pt | W12: 5 | X12: 5152 | Y12: 4000 | Z12: 10896 | AA12: 13546 | AB12: fr | AC12: 11 | AD12: 16 | AE12: 22 | AF12: 7 | AG12: 45611.98 | AH12: -2 | AI12: -2 | AJ12: -2 | AK12: 1505 | AL12: 1318 | AM12: -2 | AN12: -2 | AO12: 1932 | AP12: 1587 | AQ12: 1506 | AR12: 1450 | AS12: 1335 | AT12: -2 | AU12: -2 | AV12: -2 | AW12: 1466 | AX12: 1710 | AY12: -2 | AZ12: -2 | BA12: -2 | BB12: 1340 | BC12: -2 | BD12: -2 | BE12: -2 | BF12: 2334 | BG12: -2 | BH12: -2
A13: lemonde.fr | B13: 12500 | C13: develink | D13: 6303744 | E13: 112518 | F13: 81 | G13: 68 | H13: News/Newspapers | I13: 91 | J13: 87085 | K13: 222003 | L13: 723482 | M13: 1 | N13: -1 | O13: Le Monde.fr - Actualités et Infos en France et dans le monde | P13: 36015409 | Q13: 54183 | R13: 25471 | S13: 596 | T13: 70 | U13: fr,en,es,it,de | V13: fr,en,it,de,es,zh,pt,el,ru,sq | W13: 20 | X13: 912 | Y13: 48342 | Z13: 63226 | AA13: 60963 | AB13: fr | AC13: 55 | AD13: 98 | AE13: 357 | AF13: 31 | AG13: 45904.093 | AH13: -2 | AI13: -2 | AJ13: -2 | AK13: 12500 | AL13: -2 | AM13: -2 | AN13: -2 | AO13: 15960 | AP13: -2 | AQ13: -2 | AR13: -2 | AS13: -2 | AT13: -2 | AU13: -2 | AV13: -2 | AW13: -2 | AX13: 13530 | AY13: 13902 | AZ13: -2 | BA13: -2 | BB13: -2 | BC13: -2 | BD13: -2 | BE13: -2 | BF13: -2 | BG13: -2 | BH13: 13000
A14: mon-tote-bag.fr | B14: 13 | C14: ereferer | D14: 0 | E14: 45 | F14: 6 | G14: 21 | H14: Games/Video Games/Roleplaying | I14: 2 | J14: 0 | K14: 0 | L14: 0 | M14: 0 | N14: -1 | O14: Mon-Tote-Bag.fr | Tote bag 100% Coton et Personnalisé | P14: 70 | Q14: 29 | R14: 28 | S14: 0 | T14: 0 | U14: fr | V14: fr,en,ar,zh,nl,de,hi,id,it,ja | W14: 0 | X14: 39152836 | Y14: 0 | Z14: 2 | AA14: 4 | AC14: 0 | AD14: 0 | AE14: 0 | AF14: 0 | AG14: 45611.987 | AH14: 13 | AI14: 86 | AJ14: -2 | AK14: -2 | AL14: -2 | AM14: -2 | AN14: -2 | AO14: -2 | AP14: -2 | AQ14: -2 | AR14: -2 | AS14: -2 | AT14: -2 | AU14: -2 | AV14: -2 | AW14: -2 | AX14: -2 | AY14: -2 | AZ14: -2 | BA14: -2 | BB14: -2 | BC14: -2 | BD14: -2 | BE14: -2 | BF14: -2 | BG14: -2 | BH14: -2
A15: moovement.fr | B15: 72 | C15: linkavista | D15: 294 | E15: 164 | F15: 29 | G15: 45 | H15: Science/Technology | I15: 29 | J15: 3 | K15: 36 | L15: 129 | M15: 0 | N15: -1 | O15: Moovement - Mettez votre business en moovement | P15: 16750 | Q15: 112 | R15: 91 | S15: 0 | T15: 0 | U15: fr | V15: fr,en | W15: 0 | X15: 4166590 | Y15: 14 | Z15: 22 | AA15: 66 | AB15: fr | AC15: 0 | AD15: 0 | AE15: 0 | AF15: 0 | AG15: 45869.805 | AH15: 73 | AI15: 72 | AJ15: 72 | AK15: 107 | AL15: 87 | AM15: -2 | AN15: -2 | AO15: 108 | AP15: -2 | AQ15: 266 | AR15: -2 | AS15: -2 | AT15: 246 | AU15: -2 | AV15: -2 | AW15: 357 | AX15: -2 | AY15: 139 | AZ15: 313 | BA15: 185 | BB15: -2 | BC15: -2 | BD15: 137 | BE15: -2 | BF15: 334 | BG15: -2 | BH15: -2
A16: net67.fr | B16: 50 | C16: linksclub | D16: 2 | E16: 90 | F16: 16 | G16: 35 | H16: Business/Transportation and Logistics | I16: 10 | J16: 0 | K16: 1 | L16: 2 | M16: 0 | N16: -1 | O16: Net67-Astuces solutions et tendances numériques pour entreprises | P16: 330 | Q16: 51 | R16: 44 | S16: 0 | T16: 0 | U16: fr,en | V16: fr,en,ar,da,es | W16: 0 | X16: 16890767 | Y16: 0 | Z16: 0 | AA16: 1 | AB16: fr | AC16: 0 | AD16: 0 | AE16: 0 | AF16: 0 | AG16: 45715.834 | AH16: -2 | AI16: -2 | AJ16: -2 | AK16: -2 | AL16: -2 | AM16: 50 | AN16: -2 | AO16: -2 | AP16: -2 | AQ16: -2 | AR16: -2 | AS16: -2 | AT16: -2 | AU16: -2 | AV16: -2 | AW16: -2 | AX16: -2 | AY16: -2 | AZ16: -2 | BA16: -2 | BB16: -2 | BC16: -2 | BD16: -2 | BE16: -2 | BF16: -2 | BG16: -2 | BH16: -2
A17: outils-accessoires.fr | B17: 46 | C17: paperclub | D17: 0 | E17: 25 | F17: 3 | G17: 23 | H17: Business | I17: 0 | J17: 0 | K17: 0 | L17: 0 | M17: 0 | N17: -1 | O17: Outils Accessoires | P17: 26 | Q17: 11 | R17: 11 | S17: 0 | T17: 0 | U17: fr,en | V17: en,fr,ar,es | W17: 0 | X17: 0 | Y17: 0 | Z17: 1 | AA17: 15 | AC17: 0 | AD17: 0 | AE17: 0 | AF17: 0 | AG17: 45904.133 | AH17: -2 | AI17: -2 | AJ17: -2 | AK17: -2 | AL17: -2 | AM17: -2 | AN17: -2 | AO17: 46 | AP17: -2 | AQ17: -2 | AR17: -2 | AS17: -2 | AT17: -2 | AU17: -2 | AV17: -2 | AW17: -2 | AX17: -2 | AY17: -2 | AZ17: -2 | BA17: -2 | BB17: -2 | BC17: -2 | BD17: -2 | BE17: -2 | BF17: -2 | BG17: -2 | BH17: -2
A18: pardotconsulting.fr | B18: 81 | C18: collaborator | D18: 851 | E18: 237 | F18: 31 | G18: 35 | H18: Business | I18: 29 | J18: 3 | K18: 16 | L18: 1162 | M18: 0 | N18: -1 | O18: Pardot Consulting | P18: 5365 | Q18: 178 | R18: 151 | S18: 0 | T18: 0 | U18: fr | V18: fr,en,la | W18: 9 | X18: 3984913 | Y18: 18 | Z18: 177 | AA18: 263 | AB18: fr | AC18: 0 | AD18: 0 | AE18: 0 | AF18: 0 | AG18: 45611.977 | AH18: 105 | AI18: 94 | AJ18: 117 | AK18: 124 | AL18: -2 | AM18: -2 | AN18: 81 | AO18: 139 | AP18: 143 | AQ18: 127 | AR18: -2 | AS18: 119 | AT18: 357 | AU18: 140 | AV18: 105 | AW18: 227 | AX18: 181 | AY18: 174 | AZ18: -2 | BA18: 220 | BB18: 140 | BC18: -2 | BD18: -2 | BE18: -2 | BF18: 180 | BG18: 301 | BH18: 125
A19: pme-web.com | B19: 374 | C19: develink | D19: 2880 | E19: 831 | F19: 29 | G19: 41 | H19: Computers/Hardware | I19: 65 | J19: 66 | K19: 191 | L19: 4476 | M19: 0 | N19: -1 | O19: PME WEB | Les meilleurs outils du web | P19: 22322 | Q19: 547 | R19: 393 | S19: 1 | T19: 0 | U19: fr,en | V19: fr,en | W19: 5 | X19: 167156 | Y19: 81 | Z19: 284 | AA19: 587 | AB19: fr | AC19: 0 | AD19: 0 | AE19: 0 | AF19: 0 | AG19: 45611.98 | AH19: -2 | AI19: 576 | AJ19: 391 | AK19: 374 | AL19: -2 | AM19: -2 | AN19: 390 | AO19: 462 | AP19: 429 | AQ19: 381 | AR19: 700 | AS19: 375 | AT19: -2 | AU19: -2 | AV19: -2 | AW19: -2 | AX19: 400 | AY19: 490 | AZ19: 750 | BA19: 1000 | BB19: 850 | BC19: -2 | BD19: -2 | BE19: 405 | BF19: -2 | BG19: 748 | BH19: -2
A20: reddit.com | B20: 29 | C20: linkpublishers | D20: 999725398 | E20: 969384 | F20: 79 | G20: 80 | H20: News | I20: 95 | J20: 25264777 | K20: 48099619 | L20: 412907708 | M20: 1 | N20: -1 | O20: Reddit - The heart of the internet | P20: 1442076444 | Q20: 326388 | R20: 114354 | S20: 3526 | T20: 866 | V20: en,vi,de,fr,es,id,pt,ru,tr,ar | W20: 39 | X20: 35 | Y20: 5058899 | Z20: 2273235 | AA20: 1105965 | AB20: us | AC20: 627 | AD20: 815 | AE20: 1565 | AF20: 5919 | AG20: 45845.785 | AH20: -2 | AI20: -2 | AJ20: -2 | AK20: -2 | AL20: -2 | AM20: -2 | AN20: -2 | AO20: -2 | AP20: -2 | AQ20: -2 | AR20: -2 | AS20: -2 | AT20: 29 | AU20: -2 | AV20: -2 | AW20: -2 | AX20: -2 | AY20: -2 | AZ20: -2 | BA20: -2 | BB20: -2 | BC20: -2 | BD20: -2 | BE20: -2 | BF20: -2 | BG20: -2 | BH20: -2
A21: startups-nation.fr | B21: 49 | C21: ereferer | D21: 172 | E21: 152 | F21: 18 | G21: 36 | H21: Recreation/Travel | I21: 35 | J21: 6 | K21: 45 | L21: 57 | M21: 0 | N21: -1 | O21: Startups Nation - L'actualité des entrepreneurs et des startups | P21: 292 | Q21: 109 | R21: 98 | S21: 0 | T21: 0 | U21: fr | V21: fr,en,pt,cs,de,it,ar,zh,es,tr | W21: 9 | X21: 2335814 | Y21: 9 | Z21: 27 | AA21: 185 | AB21: fr | AC21: 0 | AD21: 0 | AE21: 0 | AF21: 0 | AG21: 45611.988 | AH21: 49 | AI21: 90 | AJ21: -2 | AK21: -2 | AL21: -2 | AM21: -2 | AN21: -2 | AO21: 154 | AP21: 65 | AQ21: -2 | AR21: 380 | AS21: -2 | AT21: -2 | AU21: -2 | AV21: -2 | AW21: -2 | AX21: -2 | AY21: 177 | AZ21: 381 | BA21: 230 | BB21: -2 | BC21: -2 | BD21: -2 | BE21: -2 | BF21: -2 | BG21: -2 | BH21: -2
